Workbook

Sheet 主要表格
B2: 主題 | D2: Blue | K2: 圖片網址 | N2: https://i.imgur.com/cWx9bjv.png | Z2: 標誌顏色 | AC2: Blue | AI2: TRUE | AJ2: 顯示 HP 條 | AN2: TRUE | AO2: 顯示 MP 條 | AS2: TRUE | AT2: 顯示 IP 條 | AX2: TRUE | AY2: 顯示 危機提醒 | CB2: When you're done with settings, you can hide this row - right click on the "2" to the far left, then select "Hide Row"!
C4: =IMAGE($N$2,2) | K4: 姓名 | M4: --- | X4: 性別 | AG4: 命刻 | AI4: 命刻名稱 | BI4: =IF(AC2="BLUE",IMAGE("https://i.imgur.com/xkhfy0X.png"), IF(AC2="GOLD",IMAGE("https://i.imgur.com/QuxLO6P.png"), IF(AC2="GRAY",IMAGE("https://i.imgur.com/IEqoBhA.png"), IF(AC2="OLIVE",IMAGE("https://i.imgur.com/UE16yt4.png"), IF(AC2="GREEN",IMAGE("https://i.imgur.com/LjvZ9Qn.png"), IF(AC2="PINK",IMAGE("https://i.imgur.com/lFXL3AE.png"), IF(AC2="PURPLE",IMAGE("https://i.imgur.com/s0hSaGK.png"), IF(AC2="BROWN",IMAGE("https://i.imgur.com/Ji8LgEb.png"), IF(AC2="WHITE",IMAGE("https://i.imgur.com/UZCbg73.png"), IF(AC2="TEAL",IMAGE("https://i.imgur.com/UmmnxUG.png"), IF(AC2="BLACK",IMAGE("https://i.imgur.com/J1vataM.png"), IF(AC2="RED",IMAGE("https://i.imgur.com/VESnnF9.png")," "))))))))))))
AM5: 0 | AN5: 4 | AP5: 個 人 簡 歷 | AQ5: 在此寫下有關角色的外貌描述或其他任何詳細資訊。 | CH5: =IF($AX$2, IF($M$10<=FLOOR($P$10/2,1), "!! 危機 !!", " ")," ")
K6: LVL | M6: =SUM(K36,AV36,K44,AV44,K52,AV52,K60) -> 0 | O6: 身份
CE7: =COUNTIF($CG$7:$CG$13, "*HP +5*") -> 0 | CF7: =C42 -> -英雄技能- | CG7: =N36
K8: 主題 | R8: 起源 | CE8: =COUNTIF($CG$7:$CG$13, "*MP +5*") -> 0 | CF8: =AN42 -> -英雄技能- | CG8: =AY36
CE9: =COUNTIF($CG$7:$CG$13, "*IP +2*") -> 0 | CF9: =C50 -> -英雄技能- | CG9: =N44 | CI9: =COUNTIF($CG$7:$CG$13, "*近戰*") -> 0
K10: HP | M10: 40 | P10: =M6+IF(CE14>0,H12*5,IF(CE15>0,H14*5, H16*5))+(CE7*5)+(IF(M6>=40,CE11*20,CE11*10))+(CE117*5)+IF(S22,AA24,0)+IF(S25,AA27,0)+IF(S28,AA30,0)+IF(S31,AA33,0) -> 40 | R10: MP | T10: 40 | W10: =M6+(5*H18)+(CE8*5)+(IF(M6>=40,CE12*20,CE12*10))+(CF117*5)+IF(S22,AC24,0)+IF(S25,AC27,0)+IF(S28,AC30,0)+IF(S31,AC33,0) -> 40 | Y10: IP | AA10: 6 | AD10: =6+(CE9*2)+(CE13*4)+IF(S22,AE24,0)+IF(S25,AE27,0)+IF(S28,AE30,0)+IF(S31,AE33,0) -> 6 | CF10: =AN50 -> -英雄技能- | CG10: =AY44 | CI10: =COUNTIF($CG$7:$CG$13, "*遠程*") -> 0
CE11: =COUNTIF(CF7:CF13,"*額外HP*") -> 0 | CF11: =C58 -> -英雄技能- | CG11: =N52 | CI11: =COUNTIF($CG$7:$CG$13, "*防具*") -> 0
C12: 屬 性 | D12: 靈巧(DEX) | H12: 8 | I12: =MIN(MAX(6, (H12 + IF($M$13, -2, 0) + IF(K12,2,0) + IF(K13,2,0) + IF($M$17, -2, 0))),12) -> 8 | K12: FALSE | X12: EXP | AA12: 物語點 | AC12: 澤尼特 | AG12: 命刻 | AI12: 命刻名稱 | CE12: =COUNTIF(CF7:CF11,"*額外MP*") -> 0 | CF12: =AN58 -> -英雄技能- | CG12: =AY52 | CI12: 職業盾牌
K13: FALSE | L13: 狀 態 | M13: FALSE | N13: 缓慢 | X13: =sum('團務紀錄'!O:O)-M6*10 -> 50 | AA13: =sum('團務紀錄'!AG:AG) -> 3 | AC13: =sum('團務紀錄'!AY:AY) -> 500 | AM13: 0 | AN13: 6 | CE13: =COUNTIF(CF7:CF13,"*額外IP*") -> 0 | CF13: =C66 -> -英雄技能- | CG13: =N60
D14: 洞察(INS) | H14: 8 | I14: =MIN(MAX(6, (H14 + IF($M$14, -2, 0) + IF(K14,2,0) + IF(K15,2,0) + IF($M$17, -2, 0))),12) -> 8 | K14: FALSE | M14: FALSE | N14: 眩暈 | CE14: =COUNTIF(CF7:CF13,"*敏捷守護之型*") -> 0 | CI14: =CONCATENATE(IF(SUM(CI9:CI12) > 0, "", " "), IF(CI9>0, "近戰 | ", ""), IF(CI10>0, "遠程 | ", ""), IF(CI11>0, "防具 | ", ""), IF(CI12>0, "盾牌 | ", "")) -> 盾牌 |
K15: FALSE | M15: FALSE | N15: 虛弱 | P15: 物理防禦 | U15: =IF(S20,I12,0)+IF(OR(AND(S25,AC25="職業"),AND(S28,AC28="盾牌"), AND(S31,AC31="盾牌")), 0, CG117)+IF(S22,AC23,0)+IF(S25,AC26,0)+IF(S28,AC29,0)+IF(S31,AC32,0) -> 8 | X15: 其他效果 | CE15: =COUNTIF(CF7:CF13,"*預知守護之型*") -> 0 | CF15: =C37 | CG15: =H37
D16: 力量(MIG) | H16: 8 | I16: =MIN(MAX(6, (H16 + IF($M$15, -2, 0) + IF(K16,2,0) + IF(K17,2,0) + IF($M$18, -2, 0))),12) -> 8 | K16: FALSE | M16: FALSE | N16: 動搖 | X16: - | CE16: =COUNTIF(CF7:CF13,"*子彈時間*") -> 0 | CF16: =C38 | CG16: =H38
K17: FALSE | M17: FALSE | N17: 憤怒 | P17: 魔法防禦 | U17: =IF(W20,I14,0)+IF(OR(AND(S25,AC25="職業"),AND(S28,AC28="盾牌"), AND(S31,AC31="盾牌")), 0, IF(CE14>0,CG117,0)) +IF(S22,AE23,0)+IF(S25,AE26,0)+IF(S28,AE29,0)+IF(S31,AE32,0) -> 8 | X17: - | CF17: =C39 | CG17: =H39
D18: 意志(WLP) | H18: 8 | I18: =MIN(MAX(6, (H18 + IF($M$16, -2, 0) + IF(K18,2,0) + IF(K19,2,0) + IF($M$18, -2, 0))),12) -> 8 | K18: FALSE | M18: FALSE | N18: 中毒 | X18: - | CF18: =C40 | CG18: =H40
K19: FALSE | X19: - | CF19: =C41 | CG19: =H41
H20: 依據當前 | K20: + | R20: 包括 靈巧？ | S20: TRUE | V20: 包括 洞察？ | W20: TRUE | X20: - | AG20: 命刻 | AI20: 命刻名稱 | CF20: =AN37 | CG20: =AS37
AM21: 0 | AN21: 8 | CF21: =AN38 | CG21: =AS38
C22: 羈 絆 | D22: 1 | R22: 裝 備 | S22: FALSE | T22: 飾品 | V22: 物品名稱 | CF22: =AN39 | CG22: =AS39
S23: 物品描述。 勾選後即可裝備。 | Z23: 0z | AB23: DEF | AD23: MDF | CF23: =AN40 | CG23: =AS40
D24: 2 | Z24: HP | AB24: MP | AD24: IP | CF24: =AN41 | CG24: =AS41
S25: FALSE | T25: 防具 | AC25: 普通 | CF25: =C45 | CG25: =H45
D26: 3 | AB26: DEF | AD26: MDF | CF26: =C46 | CG26: =H46
Z27: HP | AB27: MP | AD27: IP | CF27: =C47 | CG27: =H47
D28: 4 | S28: FALSE | T28: 主手 | AG28: 命刻 | AI28: 命刻名稱 | CF28: =C48 | CG28: =H48
AB29: DEF | AD29: MDF | AM29: 0 | AN29: 10 | CF29: =C49 | CG29: =H49
D30: 5 | Z30: HP | AB30: MP | AD30: IP | CF30: =AN45 | CG30: =AS45
S31: FALSE | T31: 副手 | CF31: =AN46 | CG31: =AS46
D32: 6 | AB32: DEF | AD32: MDF | CF32: =AN47 | CG32: =AS47
Z33: HP | AB33: MP | AD33: IP | CF33: =AN48 | CG33: =AS48
S34: =IF(SUM(CI9:CI12)>0, "✦","") | T34: =LEFT(CI14, LEN(CI14)-2) -> 盾牌 | CF34: =AN49 | CG34: =AS49
CF35: =C53 | CG35: =H53
C36: =IF(K36>=10, "★ 職業", " 職業") -> 職業 | E36: - | J36: LVL | K36: =SUM(H37:H41) -> 0 | L36: 增益 | N36: {=_xlfn.xlookup(E36,'職業技能合集'!$B:$B,'職業技能合集'!$C:$C,"-",0,1)} | AN36: =IF(AV36>=10, "★ 職業", " 職業") -> 職業 | AP36: - | AU36: LVL | AV36: =SUM(AS37:AS41) -> 0 | AW36: 增益 | AY36: {=_xlfn.xlookup(AP36,'職業技能合集'!$B:$B,'職業技能合集'!$C:$C,"-",0,1)} | CF36: =C54 | CG36: =H54
C37: =IFERROR(__xludf.DUMMYFUNCTION("ARRAYFORMULA(filter('職業技能合集'!$D:$D,'職業技能合集'!$B:$B=E36))"),"") | I37: =IFERROR(__xludf.DUMMYFUNCTION("ARRAYFORMULA(filter('職業技能合集'!$G:$G,'職業技能合集'!$B:$B=E36))"),"") | J37: 自寫招式 | N37: =IFERROR(__xludf.DUMMYFUNCTION("ARRAYFORMULA(filter('職業技能合集'!$H:$H,'職業技能合集'!$B:$B=E36))"),"") | AN37: =IFERROR(__xludf.DUMMYFUNCTION("ARRAYFORMULA(filter('職業技能合集'!$D:$D,'職業技能合集'!$B:$B=AP36))"),"") | AT37: =IFERROR(__xludf.DUMMYFUNCTION("ARRAYFORMULA(filter('職業技能合集'!$G:$G,'職業技能合集'!$B:$B=AP36))"),"") | AU37: 自寫招式 | AY37: =IFERROR(__xludf.DUMMYFUNCTION("ARRAYFORMULA(filter('職業技能合集'!$H:$H,'職業技能合集'!$B:$B=AP36))"),"") | CF37: =C55 | CG37: =H55
CF38: =C56 | CG38: =H56
CF39: =C57 | CG39: =H57
CF40: =AN53 | CG40: =AS53
CF41: =AN54 | CG41: =AS54
C42: -英雄技能- | J42: {=_xlfn.XLOOKUP(C42,'英雄技能'!A:A,'英雄技能'!C:C,0,0,1)} | AN42: -英雄技能- | AU42: {=_xlfn.XLOOKUP(AN42,'英雄技能'!A:A,'英雄技能'!C:C,0,0,1)} | CF42: =AN55 | CG42: =AS55
...

Sheet 重要公告（看完可隱藏）
A1: 致所有喜愛FU的玩家們：
A3: 這個空白的自動角色卡是以BeyondHorizon 2.14版作爲藍本，由DaCapo提供擴展不全書、由我ScarletVice完成漢化及自動化、由GARY0414完成繁中化。
A4: 沒了你們我什麽都不是，這張角色卡也不會誕生，再次獻上真誠的感謝。
A6: 呃，不過難以啓齒的是......其實這張角色卡還遠遠算不上完成。
A8: 這就要追溯到我當時獲取資料的管道開始説起了。
A9: 《Fabula Ultima最终物语》全扩展不全书V1.0(1)
A10: 這是來自中國社群的翻譯内容，目前的3個擴展（高度、科技、自然）都收錄其中。
A11: 然而最後一次更新于2023/02/22（不排除有更新的版本），并且大部分翻譯都是出自游戲初期的測試版内容。在三大擴展都已正式發售的現今，部分職業的技能都已經獲得修改，以保持更良好的畫風和平衡。
A12: 而這些正式版的技能的描述，理應都被正式啓用，一同寫進這張卡才對......
A13: ......但是當時的我好懶啊。
A14: 不全書的内容已經整理完畢，也全部寫進這張卡了。當時群内FU的人不多，想再把正式版本的内容修改進去，寫完還未必有人會用得上（？）
A15: 眼見FU要火，越來越多玩家開始選擇擴展的新職業，那我也是時候再次著手補掉剩下的坑了。
... A18: 最後在這裏列出目前的更新進度：
A19: 擴展 | B19: 職業 | C19: 職業技能 | D19: DLC技能 | E19: 英雄技能 | F19: 金手指
A20: 高度奇幻 | B20: 徽記師 | C20: 完成 | D20: 完成 | E20: 完成 | F20: 只更新了“新人類”
B21: 魔奏者 | C21: 完成 | D21: - | E21: 完成
B22: 舞者 | C22: 完成 | D22: 完成 | E22: 完成
B23: 指揮官 | C23: 完成 | D23: - | E23: 完成
A24: 科技奇幻 | B24: 機師 | C24: 完成 | D24: - | E24: 完成
B25: 靈能者 | C25: 完成 | D25: 完成 | E25: 完成
B26: 突變體 | C26: 完成 | D26: 完成 | E26: 完成
A27: 自然奇幻 | B27: 美食家 | C27: 完成 | D27: - | E27: 完成
B28: 祈喚者 | C28: 完成 | D28: - | E28: 完成
B29: 商人 | C29: 完成 | D29: - | E29: 完成
B30: 植物學家 | C30: 完成 | D30: 完成 | E30: 完成
A32: ScarletVice 啓

Sheet Main Sheet (No Reworks)
B2: THEME | D2: Blue | K2: IMAGE URL | N2: https://i.imgur.com/cWx9bjv.png | Z2: LOGO COLOR | AC2: Blue | AI2: TRUE | AJ2: show HP bar | AN2: TRUE | AO2: show MP bar | AS2: TRUE | AT2: show IP bar | AX2: TRUE | AY2: show crisis text | CB2: When you're done with settings, you can hide this row - right click on the "2" to the far left, then select "Hide Row"!
BI3: =IF(AC2="BLUE",IMAGE("https://i.imgur.com/xkhfy0X.png"), IF(AC2="GOLD",IMAGE("https://i.imgur.com/QuxLO6P.png"), IF(AC2="WHITE",IMAGE("https://i.imgur.com/IEqoBhA.png"), IF(AC2="GREEN",IMAGE("https://i.imgur.com/LjvZ9Qn.png"), IF(AC2="RED",IMAGE("https://i.imgur.com/VESnnF9.png")," ")))))
C4: =IMAGE($N$2,2) | K4: NAME | M4: --- | X4: PRONOUNS | AG4: CLOCK | AI4: CLOCK NAME | AP4: =IF(AX4>=10, "★ CLASS", " CLASS") -> CLASS | AR4: Example | AW4: LVL | AX4: =SUM(AU5:AU9) -> 5 | AY4: PASSIVE | BA4: HP +5
AM5: 0 | AN5: 4 | AP5: Skill Name | AU5: 5 | AV5: Brief skill description. | CH5: =IF($AX$2, IF($M$10<=FLOOR($P$10/2,1), "!! CRISIS !!", " ")," ")
K6: LVL | M6: =SUM(AX4,AX12,AX20,AX28,BR14,BR22,BR29) -> 5 | O6: IDENTITY
CE7: =COUNTIF($CG$7:$CG$13, "*HP +5*") -> 1 | CF7: =AP10 -> Heroic Skill | CG7: =BA4 -> HP +5
K8: THEME | R8: ORIGIN | CE8: =COUNTIF($CG$7:$CG$13, "*MP +5*") -> 0 | CF8: =AP18 | CG8: =BA12
CE9: =COUNTIF($CG$7:$CG$13, "*IP +2*") -> 0 | CF9: =AP26 | CG9: =BA20 | CI9: =COUNTIF($CG$7:$CG$13, "*melee*") -> 0
K10: HP | M10: 50 | P10: =M6+IF(CE14>0,H12*5,IF(CE15>0,H14*5, H16*5))+(CE7*5)+(IF(M6>=40,CE11*20,CE11*10))+(CE86*3)+IF(S22,AA23,0)+IF(S25,AA26,0)+IF(S28,AA29,0)+IF(S31,AA32,0) -> 50 | R10: MP | T10: 45 | W10: =M6+(5*H18)+(CE8*5)+(IF(M6>=40,CE12*20,CE12*10))+(CF86*3)+IF(S22,AC23,0)+IF(S25,AC26,0)+IF(S28,AC29,0)+IF(S31,AC32,0) -> 45 | Y10: IP | AA10: 6 | AD10: =6+(CE9*2)+(CE13*4)+IF(S22,AE23,0)+IF(S25,AE26,0)+IF(S28,AE29,0)+IF(S31,AE32,0) -> 6 | AP10: Heroic Skill | CF10: =AP34 | CG10: =BA28 | CI10: =COUNTIF($CG$7:$CG$13, "*ranged*") -> 0
CE11: =COUNTIF(CF7:CF11,"*Extra HP*") -> 0 | CF11: =BJ20 | CG11: =BU14 | CI11: =COUNTIF($CG$7:$CG$13, "*armor*") -> 0
C12: ATTRIBUTES | D12: DEXTERITY | H12: 8 | I12: =MIN(MAX(6, (H12 + IF($M$13, -2, 0) + IF(K12,2,0) + IF(K13,2,0) + IF($M$17, -2, 0))),12) -> 8 | K12: FALSE | X12: EXP | AA12: FABULA | AC12: ZENIT | AG12: CLOCK | AI12: CLOCK NAME | AP12: =IF(AX12>=10, "★ CLASS", " CLASS") -> CLASS | AW12: LVL | AX12: =SUM(AU13:AU17) -> 0 | AY12: PASSIVE | CE12: =COUNTIF(CF7:CF11,"*Extra MP*") -> 0 | CG12: =BU22 | CI12: =COUNTIF($CG$7:$CG$13, "*shield*") -> 0
K13: FALSE | L13: STATUS | M13: FALSE | N13: SLOW | P13: INITIATIVE | U13: =0+IF(S22,AA24,0)+IF(S25,AA27,0)+IF(S28,AA30,0)+IF(S31,AA33,0)+(IF(CE16>0, CG86 + CH86, 0)) -> 0 | AM13: 0 | AN13: 6 | CE13: =COUNTIF(CF7:CF11,"*Extra IP*") -> 0 | CG13: =BU29
D14: INSIGHT | H14: 8 | I14: =MIN(MAX(6, (H14 + IF($M$14, -2, 0) + IF(K14,2,0) + IF(K15,2,0) + IF($M$17, -2, 0))),12) -> 8 | K14: FALSE | M14: FALSE | N14: DAZED | BJ14: =IF(BR14>=10, "★ CLASS", " CLASS") -> CLASS | BQ14: LVL | BR14: =SUM(BO15:BO19) -> 0 | BS14: PASSIVE | CE14: =COUNTIF(CF7:CF11,"*Agile Defender*") -> 0 | CI14: =CONCATENATE(IF(SUM(CI9:CI12) > 0, "", " "), IF(CI9>0, "MELEE | ", ""), IF(CI10>0, "RANGED | ", ""), IF(CI11>0, "ARMOR | ", ""), IF(CI12>0, "SHIELD | ", ""))
K15: FALSE | M15: FALSE | N15: WEAK | P15: DEFENSE | U15: =IF(S20,I12,0)+IF(OR(AND(S25,AC25="Martial"),AND(S28,AC28="Shield"), AND(S31,AC31="Shield")), 0, CG86)+IF(S22,AC24,0)+IF(S25,AC27,0)+IF(S28,AC30,0)+IF(S31,AC33,0) -> 8 | X15: OTHER EFFECTS | CE15: =COUNTIF(CF7:CF11,"*Prophetic Defender*") -> 0 | CF15: =AP5 -> Skill Name | CG15: =AU5 -> 5
D16: MIGHT | H16: 8 | I16: =MIN(MAX(6, (H16 + IF($M$15, -2, 0) + IF(K16,2,0) + IF(K17,2,0) + IF($M$18, -2, 0))),12) -> 8 | K16: FALSE | M16: FALSE | N16: SHAKEN | X16: - | CE16: =COUNTIF(CF7:CF11,"*Bullet Time*") -> 0 | CF16: =AP6 | CG16: =AU6
K17: FALSE | M17: FALSE | N17: ENRAGE | P17: MAGIC DEFENSE | U17: =IF(W20,I14,0)+IF(OR(AND(S25,AC25="Martial"),AND(S28,AC28="Shield"), AND(S31,AC31="Shield")), 0, IF(CE14>0,CG86,0)) +IF(S22,AE24,0)+IF(S25,AE27,0)+IF(S28,AE30,0)+IF(S31,AE33,0) -> 8 | X17: - | CF17: =AP7 | CG17: =AU7
D18: WILLPOWER | H18: 8 | I18: =MIN(MAX(6, (H18 + IF($M$16, -2, 0) + IF(K18,2,0) + IF(K19,2,0) + IF($M$18, -2, 0))),12) -> 8 | K18: FALSE | M18: FALSE | N18: POISON | X18: - | CF18: =AP8 | CG18: =AU8
K19: FALSE | X19: - | CF19: =AP9 | CG19: =AU9
H20: BASE | I20: CURRENT | K20: + | R20: include DEX? | S20: TRUE | V20: include INS? | W20: TRUE | X20: - | AG20: CLOCK | AI20: CLOCK NAME | AP20: =IF(AX20>=10, "★ CLASS", " CLASS") -> CLASS | AW20: LVL | AX20: =SUM(AU21:AU25) -> 0 | AY20: PASSIVE | CF20: =AP13 | CG20: =AU13
AM21: 0 | AN21: 8 | CF21: =AP14 | CG21: =AU14
C22: BONDS | D22: 1 | R22: EQUIPMENT | S22: FALSE | T22: ACCESSORY | V22: Item Name | BJ22: =IF(BR22>=10, "★ CLASS", " CLASS") -> CLASS | BQ22: LVL | BR22: =SUM(BO23:BO27) -> 0 | BS22: PASSIVE | CF22: =AP15 | CG22: =AU15
S23: Item description. Use the checkbox to equip. | Z23: HP | AB23: MP | AD23: IP | CF23: =AP16 | CG23: =AU16
D24: 2 | Z24: INI | AB24: DEF | AD24: MDF | CF24: =AP17 | CG24: =AU17
S25: FALSE | T25: ARMOR | CF25: =AP21 | CG25: =AU21
D26: 3 | Z26: HP | AB26: MP | AD26: IP | CF26: =AP22 | CG26: =AU22
Z27: INI | AB27: DEF | AD27: MDF | CF27: =AP23 | CG27: =AU23
D28: 4 | S28: FALSE | T28: MAIN HAND | AG28: CLOCK | AI28: CLOCK NAME | AP28: =IF(AX28>=10, "★ CLASS", " CLASS") -> CLASS | AW28: LVL | AX28: =SUM(AU29:AU33) -> 0 | AY28: PASSIVE | CF28: =AP24 | CG28: =AU24
Z29: HP | AB29: MP | AD29: IP | AM29: 0 | AN29: 10 | BJ29: =IF(BR29>=10, "★ CLASS", " CLASS") -> CLASS | BQ29: LVL | BR29: =SUM(BO30:BO34) -> 0 | BS29: PASSIVE | CF29: =AP25 | CG29: =AU25
D30: 5 | Z30: INI | AB30: DEF | AD30: MDF | CF30: =AP29 | CG30: =AU29
S31: FALSE | T31: OFF-HAND | CF31: =AP30 | CG31: =AU30
D32: 6 | Z32: HP | AB32: MP | AD32: IP | CF32: =AP31 | CG32: =AU31
Z33: INI | AB33: DEF | AD33: MDF | CF33: =AP32 | CG33: =AU32
S34: =IF(SUM(CI9:CI12)>0, "✦","") | T34: =LEFT(CI14, LEN(CI14)-2) | CF34: =AP33 | CG34: =AU33
CF35: =BJ15 | CG35: =BO15
P36: LEFT COLUMN - GENERAL FEATURES | CF36: =BJ16 | CG36: =BO16
P37: This sheet is customizable - see the Additional Tables sheet! | AV37: MIDDLE COLUMN - CLASS FEATURES | BU37: RIGHT COLUMN - QUICK REFERENCE | CF37: =BJ17 | CG37: =BO17
P38: Once you have everything you want, just fill in the extra space with the normal background color. | AV38: This sheet is customizable - see the Additional Tables sheet! | BU38: This sheet is customizable - see the Additional Tables sheet! | CF38: =BJ18 | CG38: =BO18
AV39: Once you have everything you want, just fill in the extra space with the normal background color. | BU39: Once you have everything, fill in the extra space with the background color. | CF39: =BJ19 | CG39: =BO19
CF40: =BJ23 | CG40: =BO23
CF41: =BJ24 | CG41: =BO24
...

Sheet 團務紀錄
D1: 日期 | H1: 詳情 | O1: 經驗值 | V1: 日期 | Z1: 詳情 | AG1: 物語點 | AN1: 日期 | AR1: 詳情 | AY1: 澤尼特(Z)
H2: 初始 | O2: 50 | Z2: 初始 | AG2: 3 | AR2: 初始資金 | AY2: 500
C3: 經驗值 | U3: 物語點 | AM3: 錢 包

Sheet 附加表
A1: mi | K1: 其他表格 - 如需替換現有表格，請參閱說明！
B2: 主題 | D2: Black
B5: 1.選取表格區域，然後按退格鍵清除它。 | T5: 2. 點選「合併」兩次，即可先合併再取消合併。 | AK5: 3. 點選「清除格式」清除該區域。 | BA5: 4. 將「附加表格」區域複製到主頁。
BM6: 顏色並不重要。
AP15: 🡇
N16: ⮧ | BM16: ⮧
AD17: ⮧
BO36: 你完成了！
C38: 更換命刻背景（請確保選取圖表下方的儲存格），使用方向鍵可輕鬆操作
B39: 秘儀師A | Q39: 秘儀師B | AF39: 魔奏者 | AU39: 嵌合師 | BL39: 預設
B46: 指揮官 | Q46: 舞者 | AF46: 暗黑之刃 | AU46: 元素師
BL47: 王牌
B53: 熵師 | Q53: 靈能者 | AF53: 植物學家 | AU53: 狂怒鬥士
B60: 美食家 | Q60: 守護者 | AF60: 祈喚者A | AU60: 祈喚者B
BL62: 死靈術師
B67: 博學者 | Q67: 商人 | AF67: 突變體 | AU67: 吟唱者
B74: 機師 | Q74: 遊蕩者 | AF74: 神射手 | AU74: 靈師
B81: 徽記師 | Q81: 修補匠 | AF81: 旅行者 | AU81: 武器大師
A88: 左欄 - 一般特徵
B93: 額外裝備 (non-rework) | AG93: 中型版
B94: 額外裝備 | C94: - 飾品- | AG94: 額外裝備 | AH94: - 飾品-
C95: FALSE | D95: 飾品 | P95: FALSE | Q95: 飾品 | AH95: FALSE | AI95: 飾品 | AU95: FALSE | AV95: 飾品
J96: HP | L96: MP | N96: IP | W96: HP | Y96: MP | AA96: IP | AO96: HP | AQ96: MP | AS96: IP | BB96: HP | BD96: MP | BF96: IP
J97: INI | L97: DEF | N97: MDF | W97: INI | Y97: DEF | AA97: MDF | AO97: INI | AQ97: DEF | AS97: MDF | BB97: INI | BD97: DEF | BF97: MDF
C98: FALSE | D98: 飾品 | P98: FALSE | Q98: 飾品 | AH98: FALSE | AI98: 飾品 | AU98: FALSE | AV98: 飾品
J99: HP | L99: MP | N99: IP | W99: HP | Y99: MP | AA99: IP | AO99: HP | AQ99: MP | AS99: IP | BB99: HP | BD99: MP | BF99: IP
J100: INI | L100: DEF | N100: MDF | W100: INI | Y100: DEF | AA100: MDF | AO100: INI | AQ100: DEF | AS100: MDF | BB100: INI | BD100: DEF | BF100: MDF
C101: FALSE | D101: 飾品 | P101: FALSE | Q101: 飾品 | AH101: - 防具 -
J102: HP | L102: MP | N102: IP | W102: HP | Y102: MP | AA102: IP | AH102: FALSE | AI102: 防具 | AU102: FALSE | AV102: 防具
J103: INI | L103: DEF | N103: MDF | W103: INI | Y103: DEF | AA103: MDF | AO103: HP | AQ103: MP | AS103: IP | BB103: HP | BD103: MP | BF103: IP
C104: FALSE | D104: 飾品 | P104: FALSE | Q104: 飾品 | AO104: INI | AQ104: DEF | AS104: MDF | BB104: INI | BD104: DEF | BF104: MDF
J105: HP | L105: MP | N105: IP | W105: HP | Y105: MP | AA105: IP | AH105: FALSE | AI105: 防具 | AU105: FALSE | AV105: 防具
J106: INI | L106: DEF | N106: MDF | W106: INI | Y106: DEF | AA106: MDF | AO106: HP | AQ106: MP | AS106: IP | BB106: HP | BD106: MP | BF106: IP
C107: - 防具 - | AO107: INI | AQ107: DEF | AS107: MDF | BB107: INI | BD107: DEF | BF107: MDF
C108: FALSE | D108: 防具 | P108: FALSE | Q108: 防具 | AH108: - 武器 -
J109: HP | L109: MP | N109: IP | W109: HP | Y109: MP | AA109: IP | AH109: FALSE | AI109: 武器 | AU109: FALSE | AV109: 武器
J110: INI | L110: DEF | N110: MDF | W110: INI | Y110: DEF | AA110: MDF | AO110: HP | AQ110: MP | AS110: IP | BB110: HP | BD110: MP | BF110: IP
C111: FALSE | D111: 防具 | P111: FALSE | Q111: 防具 | AO111: INI | AQ111: DEF | AS111: MDF | BB111: INI | BD111: DEF | BF111: MDF
J112: HP | L112: MP | N112: IP | W112: HP | Y112: MP | AA112: IP | AH112: FALSE | AI112: 武器 | AU112: FALSE | AV112: 武器
J113: INI | L113: DEF | N113: MDF | W113: INI | Y113: DEF | AA113: MDF | AO113: HP | AQ113: MP | AS113: IP | BB113: HP | BD113: MP | BF113: IP
...

Sheet 職業技能合集
B2: 職業 | C2: 免費增益 | D2: 技能 | E2: Column 1 | F2: Max SL | G2: 最高技能等級 | H2: 說明
B3: -
B4: ——核心規則——
B5: 秘儀師 | C5: MP +5 | D5: 阿爾卡納圓環 | E5: / | F5: 4 | G5: /4 | H5: 當你在衝突中於你的回合內自願解除一個阿爾卡納時，如果該阿爾卡納在同一回合中沒有被召喚，並且你裝備了奧術類別武器，你可以立即免費執行咒語動作。你用這種方式施放的咒語其MP消耗必須小於或等於此技能的【SL×5】(你仍需支付該咒語的MP消耗)。
B6: 秘儀師 | D6: 阿爾卡納再生 | E6: / | F6: 2 | G6: /2 | H6: 當你召喚一個阿爾卡納時，你會立即恢復【SL×5】的HP。
B7: 秘儀師 | D7: 綁定和召喚 | E7: / | F7: 1 | G7: /1 | H7: 你可以將阿爾卡納與你的靈魂綁定，稍後再召喚它們。當你第一次遇到阿爾卡納時，GM會告訴你每個綁定過程的細節： 你可以使用一個動作並花費40點MP來召喚一個你已經綁定的阿爾卡納：過程細節請見下頁。 如果你在角色創建中獲得這個技能，你可以在開始遊戲之前選擇一個阿爾卡納作為已經綁定的阿爾卡納，這個阿爾卡納必須從下文的列表中選擇。此外，你只能透過探索和故事進程獲得新的阿爾卡納。
B8: 秘儀師 | D8: 緊急秘儀 | E8: / | F8: 6 | G8: /6 | H8: 只要你處於危機狀態，召喚你的阿爾卡納所需的費用降低【SL× 5】點MP。
B9: 秘儀師 | D9: 秘儀學派儀式 | E9: / | F9: 1 | G9: /1 | H9: 你可以執行秘儀學派的儀式，只要它們的效果在你所綁定的一個或多個阿爾卡納的領域內(見下頁)。 秘儀學派儀式使用【WLP+WLP】作為施法檢定。
B10: 秘儀師【Playtest】 | C10: HP +5 or MP +5 (請自行輸入選擇，方便自動表計算） | D10: 秘術再生 | E10: / | F10: 6 | G10: /6 | H10: 當你自願解除與你連結的阿爾卡納後，如果你處於危機狀態，你可以讓自己和在場的每個盟友恢復【 SL × 5】點HP。
B11: 秘儀師【Playtest】 | D11: 綁定和召喚 | E11: / | F11: 1 | G11: /1 | H11: 你可以將阿爾卡納與你的靈魂綁定，稍後再召喚它們。當你第一次遇到阿爾卡納時，GM會告訴你每個綁定過程的細節： 你可以使用一個動作並花費30點MP來召喚一個你已經綁定的阿爾卡納：過程細節請見下頁。 如果你在角色創建中獲得這個技能，你可以在開始遊戲之前選擇一個阿爾卡納作為已經綁定的阿爾卡納，這個阿爾卡納必須從下文的列表中選擇。此外，你只能透過探索和故事進程獲得新的阿爾卡納。
B12: 秘儀師【Playtest】 | D12: 幻影之力 | E12: / | F12: 6 | G12: /5 | H12: 你與阿爾卡納處於連接狀態時，你的自由攻擊、脈衝、咒語造成的傷害額外增加【SL】點。當你用脈衝或解除效果造成傷害時，如果你裝備著奧術、匕首、或連枷武器，你可以讓傷害忽略親和度。
B13: 秘儀師【Playtest】 | D13: 快速召喚 | E13: / | F13: 2 | G13: /4 | H13: 當你在衝突中於你的回合內召喚一個阿爾卡納時，最多可以選擇兩個選項： ① 召喚你的阿爾卡納所需的費用降低【SL× 5】點MP。 ② 當你召喚並連接一個阿爾卡納之後，立刻執行脈衝技能。 如果你至少選擇一個選項，則在你的下一回合開始之前不能自願解除這個阿爾卡納；如果您選擇這兩個選項，則該召喚將無法使用阿爾卡納的解除效果。
B14: 秘儀師【Playtest】 | D14: 秘儀學派儀式 | E14: / | F14: 1 | G14: /1 | H14: 你可以執行秘儀學派的儀式，只要它們的效果在你所綁定的一個或多個阿爾卡納的領域內(見下頁)。 秘儀學派儀式使用【WLP+WLP】作為施法檢定。
B15: 嵌合師 | C15: MP +5，儀式學派 | D15: 吞噬 | E15: / | F15: 5 | G15: /5 | H15: 在你用咒語對一個或多個生物造成傷害後，如果你裝備了奧術、匕首或連枷武器，你會恢復【SL×2】的MP。
B16: 嵌合師 | D16: 野性交談 | E16: / | F16: 1 | G16: /1 | H16: 你可以與野獸、魔獸和植物物種的生物溝通。
B17: 嵌合師 | D17: 惡性循環 | E17: / | F17: 1 | G17: /1 | H17: 當你用你的嵌合咒語對一個或多個生物造成傷害時，那些與你最初習得該咒語的目標生物同屬一個物種的生物都會進入中毒狀態。
B18: 嵌合師 | D18: 嵌合學派儀式 | E18: / | F18: 1 | G18: /1 | H18: 你可以施展效果屬於嵌合學派的儀式。 當你獲得這個技能時，請選擇【INS+WLP】或【MlG+WLP】。從現在開始，你的嵌合學派儀式將使用所選的屬性進行施法法檢定。
B19: 嵌合師 | D19: 咒語模仿 | E19: / | F19: 10 | G19: /10 | H19: 當你看到一個屬於野獸、怪物或植物物種的生物施展咒語時，你可以立即選擇將該咒語作為你自己的嵌合師咒語：如果你這樣做，記錄下你從什麼物種的生物那裡學到此咒語。 當你第一次習得本技能時，選擇【INS+WLP】或【MIG+WLP】，之後你的攻擊性嵌合咒語(⚡) 將使用所選的屬性進行施法檢定，而不是你所學的生物所使用的屬性檢定。 同一時間你最多能夠學會【SL+2】項不同的嵌合師咒語，如果你想記住一個新的嵌合咒語，但已經達到了你的咒語上限，你必須遺忘你的一個舊咒語，用新咒語來代替它。
B20: 暗黑之刃 | C20: HP +5，職業近戰/防具 or 職業遠程/防具 【Playtest】 (請自行輸入選擇，方便自動表計算） | D20: 疼痛 | E20: / | F20: 5 | G20: /5 | H20: 一回合一次（包括其它生物的回合），當你對一個或多個敵人造成傷害後，如果你對其中至少一個生物有羈絆，你可以恢復【SL×2】HP和【SL×2】MP。 【Playtest】
B21: 暗黑之刃 | D21: 暗黑之血 | E21: / | F21: 1 | G21: /1 | H21: 只要你處於危機狀態，你就能對暗屬性傷害和毒屬性傷害獲得抗性。
B22: 暗黑之刃 | D22: 暗黑之心 | E22: / | F22: 1 | G22: /1 | H22: 一個場景一次，當你進入危機狀態時，你可以選擇一個你所看到的，但你並沒有對其建立羈絆的生物。如果你選擇了，就對該生物產生仇恨的羈絆。
B23: 暗黑之刃 | D23: 痛苦的教訓 | E23: / | F23: 5 | G23: /5 | H23: 在另一個生物使你失去HP後(用攻擊、咒語或其他方法)，你可以立即對該生物免費執行研究動作（見74頁）。如果你這麼做了，你可以在研究動作的檢定上額外獲得此技能【SL】的加值。 記住，你只能對一個生物的單一面向研究一次。
B24: 暗黑之刃 | D24: 暗影突襲 | E24: / | F24: 5 | G24: /5 | H24: 你已經學會將你的生命力導入你的攻擊之中。你可以使用一個動作來進行暗影突襲：骰你目前的MIG骰，並且損失相當於【MIG骰結果】的HP。如果這沒有使你的HP降至0，你可以用你裝備的武器進行一次自由攻擊：如果這次攻擊擊中一個或多個目標，它造成的額外傷害等於【SL+MIG骰結果】。這次攻擊造成的所有傷害都變成了暗屬性，其傷害類型不能改變。
B25: 元素師 | C25: MP +5，儀式學派 | D25: 災難 | E25: / | F25: 3 | G25: /3 | H25: 當你施展瞬發咒語時，如果你裝備了奧術武器，你可以將該法術的總MP消耗額外增加【SL×10】點MP。如果你這樣做了，而該咒語對一個或多個生物造成了傷害，那麼它將對每個生物造成額外的傷害，每增加10點MP，額外增加5點傷害。
B26: 元素師 | D26: 元素魔法 | E26: / | F26: 10 | G26: /10 | H26: 每當你獲得此技能時，學習一個元素學派咒語(見下兩頁)。攻擊性元素咒語 (⚡) 使用【INS+WLP】進行施法檢定。
B27: 元素師 | D27: 魔法砲擊 | E27: / | F27: 3 | G27: /3 | H27: 當你施展攻擊性咒語(⚡) 時，如果你裝備有奧術武器，你的施法檢定會獲得相當於【SL×2】的加值。
B28: 元素師 | D28: 元素學派儀式 | E28: / | F28: 1 | G28: /1 | H28: 你可以施展效果屬於元素學派的儀式。 元素系的儀式使用【INS+WLP】作為魔法檢定。
B29: 元素師 | D29: 咒語之刃 | E29: / | F29: 3 | G29: /3 | H29: 當你對單一生物施展攻擊性咒語（⚡）時，如果該咒語的總MP消耗為 【SL×20】或更低，並且你裝備了一個非奧術武器，你可以選擇這些武器中的一個。如果你這樣做了，你對該咒語的施法檢定額外獲得此技能【SL】的加值，並使用所選武器的命中檢定公式；例如，透過青銅劍（見131頁）施展元素咒語的施法檢定將是【DEX+MIG+3】，而不是【INS+WLP】。 另外，若這個施法檢定有使用到DEX骰，該咒語所造成的傷害將會增加【SL×2】 的數值。 【Playtest】
B30: 熵師 | C30: MP +5，儀式學派 | D30: 吸收心智 | E30: / | F30: 5 | G30: /5 | H30: 在你受到傷害後，你可以恢復【SL×2】點MP。
B31: 熵師 | D31: 熵係魔法 | E31: / | F31: 10 | G31: /10 | H31: 每當你獲得此技能時，可以學習一個熵系咒語(見下兩頁)。 攻擊性熵係咒語 (⚡) 使用【INS+WLP】作為施法檢定。
B32: 熵師 | D32: 幸運七 | E32: / | F32: 1 | G32: /1 | H32: 你有一個幸運數字；在每次聚會開始時，這個數字是7。當你在之後的每個場景中執行檢定時，你可以用你的幸運數字與你擲出的一個骰子上的數值交換(即使這將給出一個不可能的結果，例如在一個d6上的數值是7)。如果你這樣做，替換的數值將成為你新的幸運數字。
B33: 熵師 | D33: 熵系學派儀式 | E33: / | F33: 1 | G33: /1 | H33: 你可以施展效果屬於熵學派的儀式。 元素系的儀式使用【INS+WLP】作為魔法檢定。
B34: 熵師 | D34: 竊取時間 | E34: / | F34: 4 | G34: /4 | H34: 在戰鬥中，你可以使用一個動作來幹擾時間的流動，也就是花費最多為 【SL×5】的MP。你每花費5點MP，就可以選擇一個選項： ①一個你能看見的生物會遭受緩慢狀態影響； ② 或一個你能看見的生物會從緩慢狀態中恢復； ③或一個你能看到的已經遭受緩慢狀態的生物，損失相當於【10+（SL×5）】的HP； ④或一個你能看到的生物可以立即免費執行裝備動作； ⑤或選擇一個你能看到的、在本輪中尚未進行回合的盟友：該盟友 在本回合中可以在你之後立即進行回合。 每次使用該技能時，每個選項只能被最多選擇一次。 【Playtest】
B35: 狂怒鬥士 | C35: HP +5，職業近戰/防具 | D35: 腎上腺素 | E35: / | F35: 5 | G35: /5 | H35: 只要你處於危機狀態，你就會額外造成【SL × 2】傷害(包括攻擊、咒語、阿爾卡納、物品或其他方法造成的傷害)。
B36: 狂怒鬥士 | D36: 暴怒 | E36: / | F36: 1 | G36: /1 | H36: 使用格鬥、投擲、匕首或連枷類別武器進行命中檢定時，只要兩個骰子顯示相同數字（且不是大失敗）時，你將觸發大成功。
B37: 狂怒鬥士 | D37: 不屈意志 | E37: / | F37: 4 | G37: /4 | H37: 當你花費一個或多個物語點時，你會獲得額外的好處－選擇一個選項：你會恢復【SL × 5】HP；或你恢復【SL × 5】MP；或者你自己恢復一個你選擇的狀態效果。
B38: 狂怒鬥士 | D38: 挑釁 | E38: / | F38: 5 | G38: /5 | H38: 你可以使用一個動作並花費5點MP對你能看到的一個生物執行一個【MIG+WLP】的對抗檢定並描述你如何挑釁他，如果成功，目標會進入憤怒狀態，被迫將注意力集中在你身上(他的攻擊和攻擊性咒語必須盡可能將你包括在目標中)。如果你失去知覺或離開場景，或生物不再處於憤怒狀態，或被其他人成功挑釁，本效果就結束。 本技能發起的【MIG+WLP】檢定都會獲得相當於【SL】的加值。
B39: 狂怒鬥士 | D39: 忍耐 | E39: / | F39: 5 | G39: /5 | H39: 當你執行防禦動作時，如果你選擇不為其他生物提供掩護，你恢復等於【SL乘以你的羈絆中最高強度】的HP，並選擇MIG或WLP：你選擇的屬性骰尺寸提升一階(最大為d12)，直到你的下一回合結束。
B40: 守護者 | C40: HP +5，職業防具/盾牌 | D40: 盾反 | E40: / | F40: 5 | G40: /5 | H40: 當你在你的回合中造成傷害時，如果你上回合執行防禦動作並選擇為另一個生物提供掩護，造成【SL】額外傷害。 【Playtest】
B41: 守護者 | D41: 防守掌握 | E41: / | F41: 5 | G41: /5 | H41: 只要你裝備了盾牌或職業防具，你受到的所有傷害都會減少【SL】的數值(這個效果應用在傷害親和力計算之前)。
...

Sheet 咒語合集
A1: 學派 | B1: 咒語 | C1: MP | D1: 目標 | E1: 持續時間 | F1: 效果
A2: 元素 | B2: 元素防護罩 | C2: 5 × T | D2: 至多3個生物 | E2: 場景 | F2: 你編織魔法能量，保護目標免受元素的憤怒。 選擇一種傷害類型：風、電、土、火或冰。直到此咒語結束時，每個目標獲得對所選傷害類型的抗性。
A3: 元素 | B3: 元素武器 | C3: 10 | D3: 一把武器 | E3: 場景 | F3: 你給武器注入了元素能量。選擇一種傷害類型：風、電、土、火或冰。在此咒語結束之前，該武器造成的所有傷害都會變成所選的傷害類型。如果你在施展此咒語時裝備了該武器，你可以在同一動作中用它進行一次自由攻擊。 這個咒語只能在自願的生物所裝備的武器上施放。
A4: 元素 | B4: 照明烈焰⚡ | C4: 20 | D4: 1個生物 | E4: 瞬發 | F4: 你向你的敵人射出一束火光，它的溫度極高以至於可以穿透大多數防禦。目標受到【HR+25】的火屬性傷害。 此咒語造成的傷害無視於抗性。
A5: 元素 | B5: 電流術⚡ | C5: 10 × T | D5: 至多3個生物 | E5: 瞬發 | F5: 你將電流編織成一片劈啪作響的閃電。每個被此咒語擊中的目標會受到 【HR+15】的電屬性傷害。 機會：每個被此咒語擊中的目標都會進入眩暈狀態。
A6: 元素 | B6: 冰川覆裂⚡ | C6: 10 × T | D6: 至多3個生物 | E6: 瞬發 | F6: 你給你的敵人披上了一層厚厚的霜。每個被此咒語擊中的目標都受到【HR + 15】的冰屬性傷害。 機會：每個被此咒語擊中的目標都會進入緩慢狀態。
A7: 元素 | B7: 冰凍堡壘⚡ | C7: 20 | D7: 1個生物 | E7: 瞬發 | F7: 用魔法冰柱包圍你的敵人，將敵人的體溫降低到臨界點。目標受到【HR + 25】的冰屬性傷害。 這個咒語造成的傷害忽略抗性。
A8: 元素 | B8: 伊格尼斯之火⚡ | C8: 10 × T | D8: 至多3個生物 | E8: 瞬發 | F8: 你向你的敵人釋放灼熱的彈幕，從稀薄的空氣中召喚出火焰。每個被此咒語擊中的目標受到【HR + 15】的火屬性傷害。 機會：每個被此咒語擊中的目標都會進入動搖狀態。
A9: 元素 | B9: 飛天打擊 | C9: 10 | D9: 自己 | E9: 瞬發 | F9: 狂風將帶著你的攻擊飛躍戰場。你可以立即使用你裝備的近戰武器進行自由攻擊。這個攻擊可以以只能被遠程攻擊的生物為目標。 如果你使用屬於劍、格鬥或矛類別的武器進行此攻擊，它會額外造成5點傷害。 如果你用此攻擊擊中飛行目標，你可以迫使他們立即著陸。 【Playtest】
A10: 元素 | B10: 大地震擊⚡ | C10: 10 × T | D10: 至多3個生物 | E10: 瞬發 | F10: 鋸齒狀的岩石尖刺從你的敵人下面的地面噴發出來，包圍在他們身旁。每個被此咒語擊中的目標都受到【HR + 15】的土屬性傷害。這個咒語不能針對正在飛行、漂浮、墜落或在半空中的生物。 機會：每一個被此咒語擊中的目標在他們的下一個回合中執行的動作減少一個(最少0個動作)。
A11: 元素 | B11: 雷霆⚡ | C11: 20 | D11: 1個生物 | E11: 瞬發 | F11: 你向你的敵人發出閃電。目標受到【HR + 25】的電屬性傷害。 這個咒語造成的傷害忽略抗性。
A12: 元素 | B12: 烈風⚡ | C12: 10 × T | D12: 至多3個生物 | E12: 瞬發 | F12: 你召喚風的力量對付你的敵人。每個被此咒語擊中的目標受到【HR + 15】的風屬性傷害。 機會：每個被此咒語擊中的飛行目標將強制立即降落。
... A39: 靈魂 | B39: 魂之帷幕 | C39: 5 × T | D39: 至多三個生物 | E39: 場景 | F39: 你驅動靈魂能量形成薄幕，輕柔地包裹保護隊友。選擇一種傷害類型：暗、光或毒。在此咒語結束之前，每個目標將獲得該傷害類型的抗性。 【Playtest】

Sheet DLC技能
A1: 類型 | B1: 名稱 | C1: 目標 | D1: 持續 | E1: 觸發事件/持續時間 | F1: 描述 | G1: Column 1
A2: 徽記技能 | B2: 束縛徽記 | C2: - | D2: - | F2: 攜帶者的目前屬性骰尺寸永遠不會超過他的基礎骰尺寸。這不會終止對應的提高骰尺寸的效果，只是將其無效。
A3: 徽記技能 | B3: 制物徽記 | C3: - | D3: - | F3: 當攜帶者需要在戰鬥中消耗IP時，他能摧毀這個徽記並無視那次IP消耗。
A4: 徽記技能 | B4: 絕望徽記 | C4: - | D4: - | F4: 當攜帶者在戰鬥中恢復HP或MP時，他只能恢復原本一半的數值。
A5: 徽記技能 | B5: 命運徽記 | C5: - | D5: - | F5: 當攜帶者執行一次檢定後，若你能看到他，你能消耗1點物語點，讓他重投兩顆骰子。每個檢定你只能使用本效果一次，且不能在檢定結果是大成功或大失敗時使用。
A6: 徽記技能 | B6: 元素徽記 | C6: - | D6: - | F6: 創造本徽記時，選擇一項傷害類型：風 / 電 / 暗 / 土 / 火 / 冰 / 光 / 毒。當攜帶者對一個或多個生物造成傷害時，若你能看到攜帶者，你能消耗【對所有目標造成的總傷害（計入所有來源的額外傷害）的三分之一】點MP。該傷害將轉換成創造本徽記時所選擇的傷害類型。
A7: 徽記技能 | B7: 憎惡徽記 | C7: - | D7: - | F7: 只要攜帶者處於危機，任何能看到他的敵人都必須盡可能地選為攻擊和攻擊性咒語的目標（之一）。
A8: 徽記技能 | B8: 融焊徽記 | C8: - | D8: - | F8: 創造本徽記時，選擇一項狀態：眩暈 / 動搖 / 緩慢 / 虛弱。再選擇一項效果：攜帶者獲得對該狀態的免疫；攜帶者失去對該狀態的免疫，且無法重新獲得對該狀態的免疫。
A9: 徽記技能 | B9: 禁止徽記 | C9: - | D9: - | F9: 創造本徽記時，選擇一個動作：攻擊 / 保護 / 進行目標 / 咒語 / 技能。當攜帶者執行該動作時，他損失5HP和5MP。當你的角色等級達到20級時，這個數值提高至10點；達到40級時，提高至20點。
A10: 徽記技能 | B10: 成長徽記 | C10: - | D10: - | F10: 攜帶者施展的咒語若能選擇「至多三個生物」作為目標，則提升至「至多四個生物」（MP消耗也會隨著更多的目標而增加）。
A11: 徽記技能 | B11: 變形徽記 | C11: - | D11: - | F11: 創造本徽記時，選擇一個種類：野獸 / 構造體 / 惡魔 / 元素 / 魔獸 / 植物 / 不死生物。攜帶者被視為該種類而非原本的種類（這不會改變攜帶者的各項數值，例如屬性親和和特殊規則等）。該徽記不能施加在玩家身上。
A12: 徽記技能 | B12: 繁榮徽記 | C12: - | D12: - | F12: 當攜帶者使用1點物語點，來觸發背景或羈絆時，他獲得100澤尼特。
A13: 徽記技能 | B13: 防護徽記 | C13: - | D13: - | F13: 創造本徽記時，選擇一項傷害類型：風 / 電 / 暗 / 土 / 火 / 冰 / 光 / 毒。攜帶者獲得對該類型的抗性。
... A20: 徽記技能 | B20: 弱點徽記 | C20: - | D20: - | F20: 創造本徽記時，選擇一項傷害類型：風 / 電 / 暗 / 土 / 火 / 冰 / 光 / 毒。攜帶者受到額外5點該類型的傷害。
A21: 舞步技能 | B21: 天使舞 | C21: 本身 | D21: 直到下一回合 | E21: 直到你的下個回合開始 | F21: 選擇一項：你獲得對光屬性的抗性；或將所有你的攻擊和咒語造成的傷害轉換為光屬性。
A22: 舞步技能 | B22: 女妖嚎 | C22: 一個可見你的生物 | D22: 立即 | E22: 瞬發 | F22: 選擇另一個可以看見你的生物，若他已有緩慢狀態，他立刻獲得動搖狀態。
A23: 舞步技能 | B23: 蝠之舞 | C23: 本身 | D23: 直到下一回合 | E23: 直到你的下個回合開始 | F23: 選擇一項：你獲得對暗屬性的抗性；或將所有你的攻擊和咒語造成的傷害轉換為暗屬性。
A24: 舞步技能 | B24: 傀儡戲 | C24: 本身 | D24: 直到下一回合 | E24: 直到你的下個回合開始 | F24: 選擇一項：你獲得對電屬性的抗性；或將所有你的攻擊和咒語造成的傷害轉換為電屬性。
A25: 舞步技能 | B25: 獅鷲形 | C25: 本身 | D25: 直到下一回合 | E25: 直到你的下個回合開始 | F25: 選擇一項：你獲得對風屬性的抗性；或將所有你的攻擊和咒語造成的傷害轉換為風屬性。
A26: 舞步技能 | B26: 九頭蛇 | C26: 本身 | D26: 直到下一回合 | E26: 直到你的下個回合開始 | F26: 當你受到傷害時選擇一項：恢復5點HP；恢復5點MP。
A27: 舞步技能 | B27: 海怪纏 | C27: 一個可見你的生物 | D27: 立即 | E27: 瞬發 | F27: 選擇另一個可以看見你的生物，若他已有眩暈狀態，則他立刻獲得緩慢狀態。
A28: 舞步技能 | B28: 獅子吼 | C28: 本身 | D28: 立即 | E28: 瞬發 | F28: 你立刻從一個選擇的狀態中恢復。
A29: 舞步技能 | B29: 梅納德 | C29: 一個可見你的生物 | D29: 立即 | E29: 瞬發 | F29: 選擇另一個可以看見你的生物，他損失【你目前DEX骰尺寸】點MP。
A30: 舞步技能 | B30: 米爾頓 | C30: 本身 | D30: 直到下一回合 | E30: 直到你的下個回合開始 | F30: 選擇一項：你獲得對土屬性的抗性；或將所有你的攻擊和咒語造成的傷害轉換為土屬性。
A31: 舞步技能 | B31: 夢魘麋 | C31: 一個可見你的生物 | D31: 立即 | E31: 瞬發 | F31: 選擇另一個可以看見你的生物，若他已有動搖狀態，則他立刻獲得虛弱狀態。
A32: 舞步技能 | B32: 銜尾蛇 | C32: 一個可見你的盟友 | D32: 立即 | E32: 瞬發 | F32: 選擇另一個可以看見你的、尚未在本輪進行過回合的盟友，在本輪中，他能在你的回合之後立刻開始他的回合。
... A37: 舞步技能 | B37: 雪怪足 | C37: 本身 | D37: 直到下一回合 | E37: 直到你的下個回合開始 | F37: 選擇一項：你獲得對冰屬性的抗性；或將所有你的攻擊和咒語造成的傷害轉換為冰屬性。
A38: 混合形態 | B38: 兩棲形態 | C38: - | D38: - | F38: 你可以在水下呼吸和在昏暗光線下視物的能力。每當你恢復HP時會額外恢復5點HP，並立即從你選擇的一種狀態效果中恢復。
A39: 混合形態 | B39: 追獵形態 | C39: - | D39: - | F39: 你的INS骰尺寸視為+1(最大d12)。在每個回合中，每當你第一次造成傷害時，如果你所瞄準的目標中有一個或更多處於危機狀態的生物，你會對每個生物造成5點額外傷害。
A40: 混合形態 | B40: 腕力形態 | C40: - | D40: - | F40: 你的MIG骰尺寸視為+1(最大d12)。當你成功執行檢定來填滿或清除命刻的部分刻度時，如果你的檢定包含MIG屬性，你可以填滿或抹去一個額外的命刻刻度。
A41: 混合形態 | B41: 放電形態 | C41: - | D41: - | F41: 當你用攻擊或咒語擊中目標並造成傷害時，你可以將所有這些傷害變成電屬性傷害。當你的徒手攻擊造成電屬性傷害時，那麼以你的一次徒手攻擊而損失 20 點或以上HP的目標會被施加緩慢狀態。 | G41: 改
A42: 混合形態 | B42: 神經吞噬形態 | C42: - | D42: - | F42: 每當你使用吞噬Biophagy技能時，你同時恢復【4+吞噬技能的SL】點MP。 | G42: 改
A43: 混合形態 | B43: 疊甲形態 | C43: - | D43: - | F43: 你可以將自己的物防為【13+（混合變形的SL/2）】(如果高於13，他們仍然可以自由使用自己的正常物防)。 | G43: 改
A44: 混合形態 | B44: 噴射形態 | C44: - | D44: - | F44: 當你用攻擊或咒語擊中目標並造成傷害時，你可以將所有這些傷害變成風屬性傷害。當你的徒手攻擊造成風屬性傷害時，那麼以你的一次徒手攻擊而損失 20 點或以上HP的目標會被施加虛弱狀態。 | G44: 新
A45: 混合形態 | B45: 多足形態 | C45: - | D45: - | F45: 你的徒手攻擊獲得多重(3);
A46: 混合形態 | B46: 飛翼形態 | C46: - | D46: - | F46: 你獲得飛行能力。除了在機動性方面明顯的提升外，你的近戰攻擊還可以瞄準飛行中的目標；你無法被近戰攻擊瞄準，除非攻擊者正在飛行或以某種特殊方式能夠瞄準到飛行目標。當你無法自由飛行時(如，身處於為人類體型生物設計的載具內，機師Pilot的個人載具personal vehicle內就是如此)，這種混合形態的效果無法生效。此外，當你在衝突場景中受到風屬性、電屬性或冰屬性傷害時，你將失去這個優勢直到你下一個回合開始。
A47: 混合形態 | B47: 爆燃形態 | C47: - | D47: - | F47: 當你用攻擊或咒語擊中目標並造成傷害時，你可以將所有這些傷害變成火屬性傷害。當你的徒手攻擊造成火屬性傷害時，那麼以你的一次徒手攻擊而損失 20 點或以上HP的目標會被施加眩暈狀態。 | G47: 改
A48: 混合形態 | B48: 靈巧形態 | C48: - | D48: - | F48: 你的DEX骰尺寸視為+1(最大d12)。當你成功執行檢定來填滿或清除命刻的部分刻度時，如果你的檢定包含DEX屬性，你可以填滿或抹去一個額外的命刻刻度。
A49: 混合形態 | B49: 毒物形態 | C49: - | D49: - | F49: 當你用攻擊或咒語擊中目標並造成傷害時，你可以將所有這些傷害變成毒屬性傷害。當你的徒手攻擊造成毒屬性傷害時，那麼以你的一次徒手攻擊而損失 20 點或以上HP的目標會被施加中毒狀態。 | G49: 改
A50: 心理天賦 | B50: 動能掌控 | E50: 當你造成傷害時 | F50: 這次傷害類型變爲風或電屬性，並造成等同於【2+你當前靈刻已填刻度】的額外傷害。
...

Sheet 英雄技能列表
A1: 技能名称 | B1: 学习要求 | C1: 技能效果
A2: 英雄技能
A3: ↓核心規則↓
A4: 靈巧雙手 | B4: 通用 | C4: 你可以將【雙武器戰鬥】應用在不同類別的武器，包括近戰武器與遠程武器的組合。 只要你裝備兩種不屬於同類別的武器，物防得到+2加值，每個你的回合的第二次攻擊會造成5點額外傷害。
A5: 額外HP | B5: 通用 | C5: 增加最大HP 10點（40級時增加20點）。
A6: 額外IP | B6: 通用 | C6: 增加最大IP 4點。
A7: 額外MP | B7: 通用 | C7: 增加最大MP 10點（40級時增加20點）。
A8: 額外咒語 | B8: 通用 | C8: 從元素、熵系或靈魂咒語清單中學習2個咒語，必須來自同一清單。
A9: 背水 | B9: 暗黑之刃 | C9: 只要你受到一種或多種狀態效果的影響時，每一種狀態效果使你獲得所有檢定的+1加值（最多+3點），且每一種狀態效果使得你造成的所有傷害(包括攻擊、咒語、阿爾卡納、物品或任何其他方法造成的)會有額外的2點傷害（最多6點）。 【Playtest】
A10: 阿爾卡納迴響 | B10: 秘儀師 | C10: 成功填充/消除命刻時，若阿爾卡納領域適用，額外填充/消除一格命刻。
A11: 嵌合術精通 | B11: 嵌合師 | C11: 【咒語模仿】可從構裝體、惡魔、元素生物或不死生物中，其中兩種物種身上學習咒語，每次學習增加2個嵌合咒語槽。這個技能最多獲得兩次。
A12: 彗星 | B12: 熵師 | C12: 學會熵師的終極咒語——【彗星】 —————————————————— 【彗星】、MP50、目標：特殊、持續時間：瞬發 你撕開通往宇宙的大口，從裂開的虛空中召喚星塵的碎片。選擇其中一個選項： ①你所能看見的一個生物受到60點傷害； ②你所能看見的所有敵人都受到40點傷害。 如果你達到20級或更高，傷害增加5，如果你達到40級或更高，傷害增加10。 此咒語造成的傷害沒有類型(因此不受傷害親和度的影響)
A13: 大口袋 | B13: 修補匠 | C13: 使用庫存點時，消耗量減少1（最小為1）。
A14: 卸甲真言 | B14: 吟唱者 | C14: 執行動作使動搖或危機中的士兵等級敵人撤退（消耗MP = 20 + 敵方等級一半）。
A15: 薄情者 | B15: 暗黑之刃 | C15: 攻擊單一目標時，消耗自己一半當前HP，額外傷害=10×與目標的羈絆強度，每回合限用1次。
... A34: 超魔法 | B34: 元素師 | C34: 學會元素師的終極咒語——【超魔法】，選擇其中一個屬性（火、風、電、土、冰）。 —————————————————— 【超魔法】、MP40、目標：特殊、持續時間：瞬發 你操控星球的能量，呼喚出原初之力。 選擇其中一個選項： ①你所能看見的一個生物受到50點選擇屬性的傷害； ②你所能看見的所有敵人都受到30點選擇屬性的傷害。 如果你達到20級或更高，傷害增加5，如果你達到40級或更高，傷害增加10。 此咒語造成的傷害無視抗性和免疫。
A35: ↓死亡饋贈↓
A36: 殘酷的誕生 | B36: 死靈術士 | C36: 當一個你能看到的屬於野獸、類人、怪物或植物物種的非反派NPC死亡時，你可以花費2個墳墓點，並減少你自己相當於該NPC等級的HP和MP上限。如果你這樣做，他/她/它的屍體就會變成一個服從你心靈感應命令的僕從： ·它的物種變成不死生物，並接受所有不死生物規則（見《核心規則》p305）。獲得對暗、光和毒屬性傷害的新親和力，失去原先具備的親和力，但原物種的其他規則保持不變。 ·它的等級變成士兵；如果原來的生物是菁英或冠名，GM必須相應地減少僕從的HP和MP（技能保持不變）。 ·它是個全新的生物，擁有滿值的HP、MP，狀態影響清零重置。它保留原生物的所有裝備。 ·在衝突中，你和僕從會有各自的回合，GM在設計衝突時需要將它算作一個額外的玩家角色。 ·當你休息時，你的僕從也會獲得休息的全部好處。 ·如果僕從的HP被降低到0，並且你距離它超過1個旅行日，又或者你死亡、失去知覺，你的僕從會被立即摧毀。 ·你也可以在任何時候摧毀你的僕從，但在衝突時只能在自己的回合這麼做；如果你想創造一個新的僕從，你必須先摧毀當前的那個。 ·如果你的僕人被摧毀，你的HP和MP上限會恢復正常。
A37: 哀慟採集者 | B37: 死靈術士或熵師，且必須學會抽取精魂和抽取活力咒語 | C37: 當你施放「抽取精魂」或「抽取活力」咒語時，你所恢復的MP或HP等於目標所損失的MP或HP（而不是原先的1/2）。此外，當你達到20級或更高時，你的「抽取精魂」會使目標損失【HR+20】點MP，如果你達到40級或更高時，變為【HR+25】MP，而不是通常的【HR+15】。
A38: 蠕蟲的鼓動 | B38: 死靈術士 | C38: 只要你有至少1個墳點，就會獲得對毒與暗屬性傷害的免疫，對物理屬性傷害的抗性，以及對光屬性傷害的弱點。這些親和設置會始終覆蓋任何其他來源的親和設置，只要你有至少1個墓穴點，就不會因為任何方式而改變。
A39: ↓高度奇幻↓
A40: 奧術印記 | B40: 神射手、徽記師或武器大師 | C40: 當你用奧術類武器進行攻擊並命中一個或多個生物時，該次攻擊額外造成 5 點傷害，且你可以選擇其中一個被命中的生物。如果你在本場景中施放的下一個進攻性咒語僅以該被選生物為目標，則其施法檢定在在兩個骰子得到相同出目且不是大失敗時，均被視作大成功。
A41: 雙重詠唱 | B41: 兩個或更多：元素師、熵師、靈師，且你的角色等級必須為30或更高 | C41: 在衝突中，每回合一次，如果你裝備著一個奧術類武器，你能以一個動作消耗20~50點MP，來連續兩次、無需動作地執行施放咒語動作，施放兩個咒語且無需支付它們的MP消耗。這兩個咒語的合計MP消耗必須小於等於【20+你施放這個技能時所用的MP】，且第二個咒語的MP消耗必須小於等於第一個咒語的MP消耗的一半。
A42: 利刃嫻熟 | B42: 遊蕩者或武器大師 | C42: 當你裝備一個或多個近戰、匕首類武器時，你的物防和魔防獲得+1加值。而你能夠將這些武器視為格鬥類、劍類、投擲類武器。此外，你用匕首類武器做出的攻擊能選擇那些通常不能被近戰攻擊的目標。
A43: 槍彈破擊 | B43: 神射手 | C43: 當你以交叉火力技能無效一次遠程攻擊後，如果那次攻擊的命中檢定結果是偶數，你就能用裝備著的遠程火器類武器對那個攻擊者執行一次自由攻擊。這次自由攻擊必須以他為唯一的目標，並且在計算傷害時將你的HR視為0。
A44: 永恆戰場 | B44: 指揮官 | C44: 你的主教法令、騎兵衝鋒、帝王堅壘技能的MP消耗減半。
A45: 清潔石板 | B45: 徽記師 | C45: 你能用一個動作，消耗至多30點MP，每消耗5點MP就能選擇一個你能看見的生物。這些生物從所有狀態效果中恢復，並且不再受到任何現有的、持續整個場景的咒語的效果。
A46: 雙重箭矢 | B46: 指揮官或神射手 | C46: 當你以攻擊動作使用遠程弓類武器時，若你沒有裝備除此以外的其他武器，則你能進行2次獨立的攻擊而非通常的一次（選擇同一個目標或不同的目標）。若如此做，這兩次攻擊遵循與雙武器戰鬥同樣的規則：每次攻擊都失去多重屬性且不能獲得多重屬性；計算傷害時將你的HR視為0。這個英雄技能無法和定制武器的【迅捷✦】疊加。
A47: 快速儀式 | B47: 嵌合師、元素師、熵師或靈師 | C47: 當你在衝突場景中開始一個儀式時，其儀式命刻減少2個區域（最低為4）。
A48: 瞬息之間 | B48: 武器大師，且習得招架反擊技能 | C48: 當你用一把近戰劍類武器使用招架攻擊技能時，你能將HR加入傷害運算中（無需將HR視為0）。
A49: 偉大召喚 | B49: 秘儀師，且你的角色等級必須為30或更高 | C49: 當你召喚一個阿爾卡納時，你能消耗1點物語點和一半當前HP，將你的生命力來塑造阿爾卡納的力量。若如此做，阿爾卡納會現形為一個小兵級別、惡魔物種、由你操作的生物（它視作一個盟友，且有自己獨立的回合；若你在衝突中召喚它，則它會在本輪結束後加入場景）。你無法再享受通常召喚時的連結效果。 這個召喚生物應用如下數據： · 等級等於你的角色等級 · 一個屬性D10，其餘屬性D8（由你指派） · 最大HP等於【2*基本MIG骰尺寸 + 你的最大HP/2】 · 2項傷害類型的抗性（由你選擇） · 該生物享受通常召喚時的連結效果。如果連結效果會讓阿爾卡納解除，那麼該生物會因此消失，除非你消耗20點MP作為代替 · 獲得1種近戰基礎攻擊，命中檢定使用兩項不同的屬性（由你選出），造成【HR+8】物理傷害。此外，你選擇下列中的兩項：①變成遠程攻擊；②傷害+4；③變成一種物理以外的傷害類型；④命中檢定使用單一屬性 · 該生物能以使用技能動作來產生一個解除效果，該生物也會因此消失，除非你消耗20點MP作為代替 此外，應用以下規則： · 該生物被召喚時，擁有滿HP、沒有狀態效果 · 該生物被削減至0HP時會消失，當你死亡、失去意識、離開場景、再次召喚阿爾卡納、再次使用偉大召喚時它也會消失。該生物也會在場景結束時消失，你也能單純地命令它消失（這不會觸發阿爾卡納通常的解除效果） · 任何選擇都必須在首次召喚時做出並記錄。如果你再次使用本技能召喚相同的阿爾卡納，它會繼承最初的選擇。
A50: 重裝兵 | B50: 指揮官或守護者 | C50: 只要你的主手槽位裝備了一把武器、副手槽位裝備了一個盾牌，你的攻擊就能造成5點額外傷害，且在物防上獲得+1加值。這個精通技能無法和定制武器的【物防提升】與雙重盾牌技能疊加。
A51: 鋼鐵叢林 | B51: 指揮官或武器大師 | C51: 當你用一把矛類武器，以一次近戰攻擊命中一個或多個生物後，若你沒有裝備除此以外的其他武器，你就能使用20點MP並選擇這些生物中的一個。若如此做，這次攻擊對所有目標造成的傷害減半，而你從下列動作中選擇一項：攻擊 / 保護 / 推進目標 / 施放咒語 / 使用技能。在這之後，該目標必須支付10點MP才能使用該項動作，若他無法支付，則必須選擇其他動作。這個效果持續到你的下個回合開始，或是你再次使用本技能為止。
... A63: 三刀流 | B63: 舞者或武器大師 | C63: 只要你在主副手槽位各裝備著一件屬於劍類或匕首類的單手近戰武器，你就能把你的護具槽位視為第二個副手槽位。轉換後的槽位只能裝備屬於劍類或匕首類的單手近戰武器。 （注意，精通技能靈猴握並不能將雙手武器轉換為單手武器，故它不能與三刀流組合。）當你裝備了三把劍類或匕首類的武器並使用攻擊動作時，你能以每把武器分別做出一次攻擊。這些攻擊遵循與雙武器戰鬥同樣的規則：每次攻擊都失去多重屬性且不能獲得多重屬性，且計算傷害時將你的HR視為0。
A64: ↓科技奇幻↓
A65: 奧法戰士 | B65: 元素師、神射手或武器大師，並至少學會兩個攻擊性咒語 | C65: 你可以用一個動作，使用已裝備的一把武器進行一次自由攻擊。這次攻擊只能瞄準一個敵人。如果這次攻擊命中，你在計算這次攻擊的傷害時將HR視為0。在這次攻擊結算後，如果成功命中，則你可以立即免費執行咒語動作：你這次施展的咒語必須是一個總MP消耗低於等於20的攻擊性咒語，並且只能瞄準這次攻擊的目標(你仍然需要照常花費MP和進行施法檢定)。在結算咒語傷害或其他特殊效果時，你這次的施法檢定HR視為0。
A66: 靈刻解放 | B66: 靈能者 | C66: 當你的靈刻為滿刻度時，你可以使用1個動作清空全部刻度。如果你這樣做了，你可以選擇一個選項：你對每個出現在當前場景的敵人造成20點物理傷害；或者你對一個能夠聽到你的敵人造成30點物理傷害。這個數值將在你達到20級或更高等級時提升10點，或是當你達到40級或更高等級時提升20點。
A67: 子彈時間 | B67: 遊蕩者或熵師，且必須學會閃避或竊取時間 | C67: 你的先攻獲得等同於【你的閃避SL+你的竊取時間SL】的加值。 只要你沒有裝備盾牌或職業防具，你受到的所有傷害都會減少【你的閃避SL】的數值(這個效果應用在傷害親和度之前)，並且你造成的所有傷害增加【你的竊取時間SL】的額外傷害。
A68: 誘餌 | B68: 神射手，且必須獲得鷹眼技能 | C68: 當你使用鷹眼技能並選擇第一個選項時，如果當前場景中沒有誘餌，你可以花費10點MP創造一個HP等同於【你等級的一半+(你的鷹眼SL×5)】的誘餌。 當一個能看見你誘餌的敵人對一個或多個生物造成傷害時，你的誘餌會自動代替其中一個生物受到傷害，隨機選擇(你的誘餌視作對所有傷害類型的親和力為一般，且無法改變其傷害親和力)。 當敵人將你的誘餌HP降到0時，你的誘餌會被摧毀，且你擲1d10，若出目等於或低於【3+你的鷹眼SL】，你可以立即使用你裝備的一把弓或火器類別武器執行一次自由攻擊。這次攻擊只能以該敵人為目標，且獲得等同於【你的鷹眼SL】的命中檢定加值，其傷害忽略目標的抗性和免疫。 你的誘餌無法恢復HP，並在場景結束時自動摧毀。請你一定要描述它的樣子！
A69: 夢之刃 | B69: 暗黑之刃或靈能者 | C69: 當你使用劍類別的武器使用暗影突襲技能命中一個或多個生物時，這些目標均會損失等同於【這次暗影突襲MIG骰結果】的MP。然後，如果【這次暗影突襲MIG骰結果】為8或更高，你可以選擇一個被這次攻擊命中的生物。若該生物是你的焦點或你對其有羈絆，該生物在它的下一回合將少執行一個動作(最少0個動作）。
...

Sheet 英雄技能
D1: 英雄技能
E5: 請選擇已精通的職業。
E6: （精通為職業技能達到最大LV 10）
E7: 祈喚者 | H7: - | K7: - | N7: - | Q7: - | T7: - | W7: -
A9: -英雄技能- | E9: 英雄技能 | H9: 學習要求 | N9: 效果
A10: =E10 -> 魔法折射 | C10: =N10 -> 當一個你能看見的敵人施展攻擊性咒語攻擊你時，如果他的施法檢定結果為偶數，你可以立即免費使用元素祈喚技能，且無視MP消耗(在這次攻擊性咒語結算完後進行)；這次元素祈喚不能是「元素詛咒」祈喚，且它只能瞄準該敵人(你不能使用聯結元素技能加持它)。 | E10: =IFERROR(__xludf.DUMMYFUNCTION("VSTACK( IFERROR(FILTER('英雄技能列表'!A:A, ISNUMBER(SEARCH(E7, '英雄技能列表'!$B:$B))), "" ""), IFERROR(FILTER('英雄技能列表'!A:A, ISNUMBER(SEARCH(H7, '英雄技能列表'!$B:$B))), "" ""), IFERROR(FILTER('英雄技能列表'!A:A, ISNUMBER(SEARCH(K7, '英雄技能列表'!$B:$B))), "" ""), IFERROR(FILTER('英雄技"&"能列表'!A:A, ISNUMBER(SEARCH(N7, '英雄技能列表'!$B:$B))), "" ""), IFERROR(FILTER('英雄技能列表'!A:A, ISNUMBER(SEARCH(Q7, '英雄技能列表'!$B:$B))), "" ""), IFERROR(FILTER('英雄技能列表'!A:A, ISNUMBER(SEARCH(T7, '英雄技能列表'!$B:$B))), "" ""), IFERROR(FILTER('英雄技能列表'!A:A, ISNUMBER(SEARCH(W"&"7, '英雄技能列表'!$B:$B))), "" ""))"),"魔法折射") -> 魔法折射 | H10: =IFERROR(__xludf.DUMMYFUNCTION("VSTACK( IFERROR(FILTER('英雄技能列表'!B:B, ISNUMBER(SEARCH(E7, '英雄技能列表'!$B:$B))), "" ""), IFERROR(FILTER('英雄技能列表'!B:B, ISNUMBER(SEARCH(H7, '英雄技能列表'!$B:$B))), "" ""), IFERROR(FILTER('英雄技能列表'!B:B, ISNUMBER(SEARCH(K7, '英雄技能列表'!$B:$B))), "" ""), IFERROR(FILTER('英雄技"&"能列表'!B:B, ISNUMBER(SEARCH(N7, '英雄技能列表'!$B:$B))), "" ""), IFERROR(FILTER('英雄技能列表'!B:B, ISNUMBER(SEARCH(Q7, '英雄技能列表'!$B:$B))), "" ""), IFERROR(FILTER('英雄技能列表'!B:B, ISNUMBER(SEARCH(T7, '英雄技能列表'!$B:$B))), "" ""), IFERROR(FILTER('英雄技能列表'!B:B, ISNUMBER(SEARCH(W"&"7, '英雄技能列表'!$B:$B))), "" ""))"),"元素師、熵師、祈喚者或徽記師，且必須獲得元素祈喚技能") -> 元素師、熵師、祈喚者或徽記師，且必須獲得元素祈喚技能 | N10: =IFERROR(__xludf.DUMMYFUNCTION("VSTACK( IFERROR(FILTER('英雄技能列表'!C:C, ISNUMBER(SEARCH(E7, '英雄技能列表'!$B:$B))), "" ""), IFERROR(FILTER('英雄技能列表'!C:C, ISNUMBER(SEARCH(H7, '英雄技能列表'!$B:$B))), "" ""), IFERROR(FILTER('英雄技能列表'!C:C, ISNUMBER(SEARCH(K7, '英雄技能列表'!$B:$B))), "" ""), IFERROR(FILTER('英雄技"&"能列表'!C:C, ISNUMBER(SEARCH(N7, '英雄技能列表'!$B:$B))), "" ""), IFERROR(FILTER('英雄技能列表'!C:C, ISNUMBER(SEARCH(Q7, '英雄技能列表'!$B:$B))), "" ""), IFERROR(FILTER('英雄技能列表'!C:C, ISNUMBER(SEARCH(T7, '英雄技能列表'!$B:$B))), "" ""), IFERROR(FILTER('英雄技能列表'!C:C, ISNUMBER(SEARCH(W"&"7, '英雄技能列表'!$B:$B))), "" ""))"),"當一個你能看見的敵人施展攻擊性咒語攻擊你時，如果他的施法檢定結果為偶數，你可以立即免費使用元素祈喚技能，且無視MP消耗(在這次攻擊性咒語結算完後進行)；這次元素祈喚不能是「元素詛咒」祈喚，且它只能瞄準該敵人(你不能使用聯結元素技能加持它)。") -> 當一個你能看見的敵人施展攻擊性咒語攻擊你時，如果他的施法檢定結果為偶數，你可以立即免費使用元素祈喚技能，且無視MP消耗(在這次攻擊性咒語結算完後進行)；這次元素祈喚不能是「元素詛咒」祈喚，且它只能瞄準該敵人(你不能使用聯結元素技能加持它)。 | AX10: -
A11: =E11 -> 內蘊源泉 | C11: =N11 -> 當你獲得這個英雄技能，或每當你進行休息後，你可以選擇一種元素來源：風土火電或冰。直到你再次休息，你都將獲得以下增益： · 在每個場景中你都可以一直調用你所選的元素源泉，這不會佔用你在本場景中原本可以調用的元素源泉數量。 · 你可以操控該屬性，施展效果屬於元素學派的儀式。 · 你獲得你所選擇的元素來源對應的傷害類型的傷害抗性。 · 當你造成傷害時，你可以將所有傷害轉換為你所選擇的元素來源對應的傷害類型。如果你這樣做了，這些傷害會無視傷害抗性。 | E11: =IFERROR(__xludf.DUMMYFUNCTION("""COMPUTED_VALUE"""),"內蘊源泉") -> 內蘊源泉 | H11: =IFERROR(__xludf.DUMMYFUNCTION("""COMPUTED_VALUE"""),"祈喚者") -> 祈喚者 | N11: =IFERROR(__xludf.DUMMYFUNCTION("""COMPUTED_VALUE"""),"當你獲得這個英雄技能，或每當你進行休息後，你可以選擇一種元素來源：風土火電或冰。直到你再次休息，你都將獲得以下增益： · 在每個場景中你都可以一直調用你所選的元素源泉，這不會佔用你在本場景中原本可以調用的元素源泉數量。 · 你可以操控該屬性，施展效果屬於元素學派的儀式。 · 你獲得你所選擇的元素來源對應的傷害類型的傷害抗性。 · 當你造成傷害時，你可以將所有傷害轉換為你所選擇的元素來源對應的傷害類型。如果你這樣做了，這些傷害會無視傷害抗性。") -> 當你獲得這個英雄技能，或每當你進行休息後，你可以選擇一種元素來源：風土火電或冰。直到你再次休息，你都將獲得以下增益： · 在每個場景中你都可以一直調用你所選的元素源泉，這不會佔用你在本場景中原本可以調用的元素源泉數量。 · 你可以操控該屬性，施展效果屬於元素學派的儀式。 · 你獲得你所選擇的元素來源對應的傷害類型的傷害抗性。 · 當你造成傷害時，你可以將所有傷害轉換為你所選擇的元素來源對應的傷害類型。如果你這樣做了，這些傷害會無視傷害抗性。 | AX11: 通用
A12: =E12 -> 五行源泉之力 | C12: =N12 -> 每當你在衝突場景中使用一次元素祈喚後，你和你能看見的一個盟友的一個屬性骰尺寸+1(至多到d12)。這個效果持續到你下一回合結束或直到你再次使用這個技能，並且提升的屬性類型取決於你使用的元素源泉種類：風之源泉(INS)，土之源泉(由你自選)，火之源泉(DEX)，電之源泉(MIG)，或者冰之源泉(WLP)。 | E12: =IFERROR(__xludf.DUMMYFUNCTION("""COMPUTED_VALUE"""),"五行源泉之力") -> 五行源泉之力 | H12: =IFERROR(__xludf.DUMMYFUNCTION("""COMPUTED_VALUE"""),"祈喚者") -> 祈喚者 | N12: =IFERROR(__xludf.DUMMYFUNCTION("""COMPUTED_VALUE"""),"每當你在衝突場景中使用一次元素祈喚後，你和你能看見的一個盟友的一個屬性骰尺寸+1(至多到d12)。這個效果持續到你下一回合結束或直到你再次使用這個技能，並且提升的屬性類型取決於你使用的元素源泉種類：風之源泉(INS)，土之源泉(由你自選)，火之源泉(DEX)，電之源泉(MIG)，或者冰之源泉(WLP)。") -> 每當你在衝突場景中使用一次元素祈喚後，你和你能看見的一個盟友的一個屬性骰尺寸+1(至多到d12)。這個效果持續到你下一回合結束或直到你再次使用這個技能，並且提升的屬性類型取決於你使用的元素源泉種類：風之源泉(INS)，土之源泉(由你自選)，火之源泉(DEX)，電之源泉(MIG)，或者冰之源泉(WLP)。 | AX12: 秘儀師
A13: =E13 -> 陰陽流轉 | C13: =N13 -> 當你在一個回合中初次造成暗、土、冰或物理屬性傷害時，你獲得1個陰點。如果你此時還擁有至少1陽點，你造成5額外傷害。 當你在一個回合中初次造成風、電、火或光屬性傷害時，你獲得1陽點。如果你此時還擁有至少1個陰點，你造成5額外傷害。 在你回合結束時，若陰點或陽點某一極有3點及以上，且另一極至少有1點，則你失去所有陰陽點，並根據失去的兩極點數多寡，執行下列效果其中之一。 （若兩極均衡，則執行兩個效果）: ◆陰盛：目前場景的所有敵人失去等同於【你等級的一半】的MP。 ◆陽盛：當前場景中一個你能看見的生物恢復等同於【你的等級】的MP。 你只能在衝突中獲得陰陽點數，並且在每個場景結束時失去所有陰陽點數。 | E13: =IFERROR(__xludf.DUMMYFUNCTION("""COMPUTED_VALUE"""),"陰陽流轉") -> 陰陽流轉 | H13: =IFERROR(__xludf.DUMMYFUNCTION("""COMPUTED_VALUE"""),"舞者、元素師、靈能者或祈喚者") -> 舞者、元素師、靈能者或祈喚者 | N13: =IFERROR(__xludf.DUMMYFUNCTION("""COMPUTED_VALUE"""),"當你在一個回合中初次造成暗、土、冰或物理屬性傷害時，你獲得1個陰點。如果你此時還擁有至少1陽點，你造成5額外傷害。 當你在一個回合中初次造成風、電、火或光屬性傷害時，你獲得1陽點。如果你此時還擁有至少1個陰點，你造成5額外傷害。 在你回合結束時，若陰點或陽點某一極有3點及以上，且另一極至少有1點，則你失去所有陰陽點，並根據失去的兩極點數多寡，執行下列效果其中之一。 （若兩極均衡，則執行兩個效果）: ◆陰盛：目前場景的所有敵人失去等同於【你等級的一半】的MP。 ◆陽盛：當前場景中一個你能看見的生物恢復等同於"&"【你的等級】的MP。 你只能在衝突中獲得陰陽點數，並且在每個場景結束時失去所有陰陽點數。") -> 當你在一個回合中初次造成暗、土、冰或物理屬性傷害時，你獲得1個陰點。如果你此時還擁有至少1陽點，你造成5額外傷害。 當你在一個回合中初次造成風、電、火或光屬性傷害時，你獲得1陽點。如果你此時還擁有至少1個陰點，你造成5額外傷害。 在你回合結束時，若陰點或陽點某一極有3點及以上，且另一極至少有1點，則你失去所有陰陽點，並根據失去的兩極點數多寡，執行下列效果其中之一。 （若兩極均衡，則執行兩個效果）: ◆陰盛：目前場景的所有敵人失去等同於【你等級的一半】的MP。 ◆陽盛：當前場景中一個你能看見的生物恢復等同於【你的等級】的MP。 你只能在衝突中獲得陰陽點數，並且在每個場景結束時失去所有陰陽點數。 | AX13: 嵌合師
A14: =E14 | C14: =N14 | E14: =IFERROR(__xludf.DUMMYFUNCTION("""COMPUTED_VALUE""")," ") | H14: =IFERROR(__xludf.DUMMYFUNCTION("""COMPUTED_VALUE""")," ") | N14: =IFERROR(__xludf.DUMMYFUNCTION("""COMPUTED_VALUE""")," ") | AX14: 暗黑之刃
A15: =E15 | C15: =N15 | E15: =IFERROR(__xludf.DUMMYFUNCTION("""COMPUTED_VALUE""")," ") | H15: =IFERROR(__xludf.DUMMYFUNCTION("""COMPUTED_VALUE""")," ") | N15: =IFERROR(__xludf.DUMMYFUNCTION("""COMPUTED_VALUE""")," ") | AX15: 元素師
A16: =E16 | C16: =N16 | E16: =IFERROR(__xludf.DUMMYFUNCTION("""COMPUTED_VALUE""")," ") | H16: =IFERROR(__xludf.DUMMYFUNCTION("""COMPUTED_VALUE""")," ") | N16: =IFERROR(__xludf.DUMMYFUNCTION("""COMPUTED_VALUE""")," ") | AX16: 熵師
A17: =E17 | C17: =N17 | E17: =IFERROR(__xludf.DUMMYFUNCTION("""COMPUTED_VALUE""")," ") | H17: =IFERROR(__xludf.DUMMYFUNCTION("""COMPUTED_VALUE""")," ") | N17: =IFERROR(__xludf.DUMMYFUNCTION("""COMPUTED_VALUE""")," ") | AX17: 狂怒鬥士
A18: =E18 | C18: =N18 | E18: =IFERROR(__xludf.DUMMYFUNCTION("""COMPUTED_VALUE""")," ") | H18: =IFERROR(__xludf.DUMMYFUNCTION("""COMPUTED_VALUE""")," ") | N18: =IFERROR(__xludf.DUMMYFUNCTION("""COMPUTED_VALUE""")," ") | AX18: 守護者
A19: =E19 | C19: =N19 | E19: =IFERROR(__xludf.DUMMYFUNCTION("""COMPUTED_VALUE""")," ") | H19: =IFERROR(__xludf.DUMMYFUNCTION("""COMPUTED_VALUE""")," ") | N19: =IFERROR(__xludf.DUMMYFUNCTION("""COMPUTED_VALUE""")," ") | AX19: 博學士
A20: =E20 | C20: =N20 | AX20: 吟唱者
A21: =E21 | C21: =N21 | AX21: 遊蕩者
A22: =E22 | C22: =N22 | AX22: 神射手
A23: =E23 | C23: =N23 | AX23: 靈師
A24: =E24 | C24: =N24 | AX24: 修補匠
A25: =E25 | C25: =N25 | AX25: 旅人
A26: =E26 | C26: =N26 | AX26: 武器大師
A27: =E27 | C27: =N27
A28: =E28 | C28: =N28 | AX28: 死靈術士
A29: =E29 | C29: =N29
A30: =E30 | C30: =N30 | AX30: 徽記師
A31: =E31 | C31: =N31 | AX31: 魔奏者
A32: =E32 | C32: =N32 | AX32: 舞者
A33: =E33 | C33: =N33 | AX33: 指揮官
A34: =E34 | C34: =N34
A35: =E35 | C35: =N35 | AX35: 機師
A36: =E36 | C36: =N36 | AX36: 靈能者
A37: =E37 | C37: =N37 | AX37: 突變體
A38: =E38 | C38: =N38
A39: =E39 | C39: =N39 | AX39: 美食家
A40: =E40 | C40: =N40 | AX40: 祈喚者
A41: =E41 | C41: =N41 | AX41: 商人
A42: =E42 | C42: =N42 | AX42: 植物學家
A43: =E43 | C43: =N43
A44: =E44 | C44: =N44
...

Sheet 金手指
A1: 名稱 | B1: 人設提示 | C1: 描述
A2: 無 | B2: 無 | C2: 無
A3: ↓高度奇幻類↓ | B3: - | C3: -
A4: 草木成精（高奇） | B4: 你是一種有認知能力的植物生物，且具有人類等級智慧。你是屬於魔法實驗的結果？還是屬於某一特殊的生物？你喜歡特定種類的植物、花卉或樹木嗎？你與其他植物物種生物，以及世界上的樹木和森林有關係嗎？ | C4: 選擇一種狀態：眩暈、憤怒或動搖狀態。你免疫所選擇的狀態。但是，你也會獲得你所選擇的一項傷害易傷：風、電、土、火或冰屬性。 你也可以學習一項NPC咒語（可見於《核心規則》第310~311頁；你不能選擇「毀蕩」咒語；如果需要進行施法檢定，請使用【INS+WLP】），請根據需要來自訂該咒語（名稱、傷害類型、狀態效果等）。當你在陽光下施展該咒語時，其總MP消耗量將減少5點（最低為0MP）。
A5: 被詛咒之人（高奇） | B5: 你承受著一個奇怪的詛咒。它會表現出哪些超自然的效果？你是如何被詛咒的？這是你運氣不好，還是對你所做的某件事的懲罰？如何解除詛咒？ | C5: 當你獲得這個金手指時，描述你的詛咒的性質，並將其與你所在世界中存在的威脅之一聯繫起來。一旦這項威脅得到解決，你終於將獲得機會來擺脫詛咒——請描述你在你的打算中這會如何發展。 例如：你使用武器時常常會打空；你的存在會引起人們的恐懼感；你的魔法常常會引發各種意外結果；你伸手範圍內的生物會感到全身劇痛等等。 當你要進行一次檢定時，你可以描述你的詛咒是如何阻礙你的，並自動獲得這次檢定的大失敗（這2個骰子都被視為你骰出了1點）。如果你這樣做了，你將獲得2個物語點而不是1個，並且可以使用一個機會。 當你成功打破詛咒時，你立即獲得一個你所選擇的英雄技能（你甚至可以選擇你不符合前提要求的英雄技能，除非這個前提要求包含了你沒有的技能）。你因此可以選擇你沒有的職業的英雄技能。
A6: 元素之魂（高奇） | B6: 你深深融入了自然元素的力量。你是一個元素生物的子嗣？還是你與某種精神體進行了融合？誰會試圖利用你的特殊本性？誰怕你？ | C6: 你選擇一項傷害類型並獲得對應的抗性：風、電、土、火或冰屬性；此外，當你造成傷害時，你可以選擇將其傷害類型改為你之前選擇的傷害類型。但是，你也會獲得這5種傷害類型中另一項你所選擇的傷害類型的易傷。你也可以獲得施展效果屬於元素學派的儀式的能力，但前提是這些儀式是操控你所選擇的元素。
A7: 空手道 | B7: 你已經放棄了武器的使用，而只依靠你的雙手和雙腳。你發展這種戰鬥風格是處於必要還是處於選擇權？是因為你那可怕的身體構造嗎？還是說你的刀劍在過去已經奪走了太多人的生命？ | C7: 你的徒手攻擊造成6點額外傷害。如果你達到30級或更高，這個數值會提升至10點額外傷害。此外，當你沒有裝備武器和盾牌（除了徒手攻擊）時，你會獲得物防+1和魔防+1的加值。
A8: 被束縛的心 | B8: 你遵守某個人或組織的戒律已經很久了,以至於你之前的整個生活都建立在此基礎上.然而,現在你開始從另一個（陰暗的、客觀的、革新的的或跨越階級的）視角來審視這些規則，你的內心出現了動搖。你第一次開始懷疑它們是在什麼時候？ | C8: 只有當你的角色主題是懷疑時，你才能獲得這個金手指，只要你擁有這個金手指，你的角色主題就不能被任何方式改變。 當你獲得這個金手指時，你與那個塑造你的一個NPC或組織建立起一個羈絆。這個羈絆初始擁有3種情緒，只要你擁有這個金手指，那麼這個羈絆就不會因為任何方式失去或消除（你仍然可以在休息時改變羈絆的情緒）。此外，為這個NPC或組織創造他們至關重要的3條戒律commandments：每一條戒律都必須是你必須做到的事情，或者是你絕對不能做的事情。 例如：龍王（永遠服從龍族，永遠不顯露出軟弱，永遠不熄滅火焰）；蒼白教會（永遠忠誠於信仰；永遠不要懷疑牧師；永遠不要聽惡魔說什麼） 當你在每個場景中第一次違反戒律時，你會立即受到動搖和虛弱狀態效果，並失去當前一半的HP和MP（向下取整）的懲罰，但也會獲得2點物語點。 如果你在休息場景中違反了戒律，你將在休息結束並得到恢復之後再受到懲罰效果；如果你在同一場景中多次違反戒律，懲罰和物語點不會重複獲得。 當你累積違反了6次戒律之後，你再違反戒律時將忽略受到的懲罰，除非它發生在一個遵循或體現你的戒律的反派面前。 如果你不確定某個情況是否符合此金手指的標準，那麼你總是擁有最終解釋權。不過請你盡可能真誠誠實地做出決定。 在第7次違反戒律時，你將失去這個金手指，並將角色主題改為以下主題之一：歸屬、罪惡感、正義或復仇。然後，你立即獲得一個你的職業可以獲得的英雄技能（你甚至可以選擇一個你不滿足前提要求的英雄技能，除非其中包含你沒學會的技能）；最後，你恢復所有的HP和MP和所有狀態。從此以後，你所有的羈絆的強度+1。 （例如，一個有著3種情緒的羈絆將視為強度4）。
A9: 飛行（高奇） | B9: 你屬於一種具有飛行或懸浮能力的類人生物的遺孤。你的這項能力是如何運作的？它是一種神奇的能力，還是你長有翅膀？這項特殊能力是如何影響本國人民的歷史和社會的？人們通常對你有​​什麼反應？ | C9: 你獲得飛行能力。除了在機動性方面的明顯優勢外，你的近戰攻擊可以瞄準飛行生物，並且除非攻擊者正在飛行或以某種特殊方式能夠攻擊到飛行目標，否則你不能被近戰攻擊瞄準。 當處於危機狀態或無法自由飛行時（例如，當你位於為人類大小的生物設計的載具內或狹窄的走廊內），你將失去此金手指提供的好處。此外，當你在衝突場景中受到風、電、或冰屬性傷害時，你將失去此金手指提供的好處，直到你下一回合開始。
A10: 來自遙遠的世界（高奇） | B10: 你在這裡的存在是一種異常，是命運編織中一個意想不到的結：這片土地的規則有時無法約束你。你是來自於不同的星球？還是來自不同的時代？你是以何種方式到來的，又是什麼時候到來的？你認為你還有機會回去嗎？如果可以的話，你會這樣做嗎？你受到了什麼可怕的威脅嗎？ | C10: 當你參與衝突場景時，你立即自動獲得1點物語點。 此外，當你大失敗時你可以立即進行一次觸發特質來進行重骰檢定結果（如果你這樣做了，你就不會因為這次大失敗而獲得物語點）
A11: 光榮的命運 | B11: 你被一個神奇的預言縈繞，一個對美好世界充滿希望的預言。那個預言是由誰說出來或寫出來的？你是選擇擁抱命運，還是被命運的重擔壓垮？是否有人在你的內心種下了懷疑的種子？ | C11: 當你獲得這個金手指時，寫下這則有關於你的預言。請與團隊中的其他成員進行討論，並將其與你的世界中已有的威脅或突發事件聯繫起來，並描述什麼跡像或徵兆將你標記為預言中的那位「命定之人\預言之子」。 例如：“戴紅寶石項鍊的男孩將把水帶回荒蕪平原”，或“帶有烙印之人將殺死混沌魔龍”。 在每個章節結束時（通常為1次4小時的聚會），在分配XP之前，請認真和仔細地思考在本章節中發生的事件，並從以下5個選項中選擇一項，但記得多和團隊中的其他成員進行交流總是好事： ·你已經實現了預言：你失去這個金手指，恢復全部的HP、MP和狀態，並立即獲得一個你的職業可以獲得的英雄技能（你甚至可以選擇一個你不滿足前提要求的英雄技能，除非其中包含你沒學會的技能）。 ·你的行為符合預言：恢復全部的HP、MP和狀態。 ·你的行為既不符合也不違背預言：無事發生。 ·你違背了預言：獲得1點物語點。 ·你打破了預言：你失去這個金手指，獲得6點物語點，並立即獲得一個你的職業可以獲得的英雄技能（你甚至可以選擇一個你不滿足前提要求的英雄技能，除非其中包含你沒學會的技能）。 一旦你選擇了第一個或最後一個選項，預言在你的世界中的作用就結束了。即使在遊戲後期出現了與預言相符合的情況，但這個金手指的效果也不復存在了：你可以自由決定自己的命運，並根據自己內心的道德準則來行動。又或者你一直都是這樣的人？
A12: 傳家寶 | B12: 你擁有一件或多件獨特的裝備。這些東西是你的家族傳承下來的？還是某個你珍惜之人送給你的禮物？這些東西上有什麼奇怪或危險的傳說或謠言嗎？有誰會不擇手段地想要從你手中奪走它們嗎？ | C12: 你獲得1件價值在1200zenit或更低的稀有物品，或2件價值在800zenit的稀有物品。你可以從稀有物品範例表中直接選擇合適的物品，也可以與團隊中的其他成員一起來設計這些物品。 每個章節結束時（通常為1次4小時的聚會），GM可能會給你1點物語點，來應對由於你攜帶的物品的獨特性質而突然出現的複雜情況（例如有人對你發出決鬥或出現某些被其魔法吸引來的怪物）。未經玩家同意，透過此金手指獲得的物品不能被銷毀、損壞、遺失或被竊。
... A61: (不太)忠誠的僕人 | B61: 你是另一個角色的左膀右臂。 ta可能命中註定要成就一番大事，但現在急需你的幫助，又或者ta對常識一無所知，需要一個打點日常事務的助手。是怎樣的承諾、債務，或是誓言在束縛你，讓你為ta效力？你是用怎樣的態度看待ta的？你認為ta最大的缺點是什麼？你有沒有想過，自己才是應該站在聚光燈下的人？你為ta保守了什麼秘密嗎？ | C61: 當你獲得此金手指時，選擇另一個玩家角色：該角色成為你的主人。你們兩個對彼此創造一個羈絆；你的羈絆在忠誠和懷疑中選擇一個情緒，你主人對你的羈絆在讚賞、自卑或懷疑中選擇一個情緒。 [請確保控制你主人角色的玩家同意你們之間的關係，且這種關係貼合你所想要探索的，有關此金手指的情節發展。 ] 當你的主人執行一次檢定時，如果你在同一場景，你可以選擇提供幫助：你將會使用團體檢定（見核心規則書，p50）的規則，但你的支援檢定自動成功（註：即你可以讓你主人的檢定自動+1）。如果你在衝突場景中這麼做，你不會因此在本輪中失去自己的回合。 （因此你可以忽略團隊合作的限制，請參閱核心規則書，p76）。 如果你的主人接受你的幫助，你獲得1依賴點。 每章節限一次（通常為一次4小時的聚會），在結算XP之前，擲2d20。若擲骰結果等於或低於你目前的角色等級，你獲得1依賴點數。隨後，如果你擁有20以上的依賴點，在以下選項中選擇一個： ◆挑戰：現在是時候讓你的主人接受考驗了。與控制你主人的玩家一同，敘述一場決鬥、一次挑戰或類似的某種比賽，你的主人必須藉此證明自己不需要你的幫助，並且贏過你。然後，你失去此金手指，並獲得一個你所選擇的英雄技能（你甚至可以選擇你不符合前提要求的英雄技能，除非這個前提要求包含了你沒有的技能）。你因此可以選擇你沒有的職業的英雄技能。 ◆背叛：至暗之時已到，你在陰影中展現出自己的本性。與控制你主人的玩家一同，敘述你的背叛，並一致同意得到一個恰當的後果（比如失去一件重要物品，一個恐怖敵人的複蘇，或者你主人的主題因此改變）。然後，你的玩家角色成為一個次要反派或主要反派（由GM選擇），並且你創造一個新角色。

Sheet 植物學家相關
A1: 花園
A2: 當你種下一顆魔法種子時，它會在你的花園中扎根，直到被移除。你的花園是一個抽象空間，其外觀隨你角色的造型而異：它可能是背上的一個花盆、劍身上的一個凹槽，甚至是腳下的地面。你的花園一次只能容納一顆魔法種子，且任何位於你花園中的魔法種子都會在每個場景結束時自動移除。
A5: 生長命刻
A6: 當你獲得魔法種子傳記技能時，你也會獲得一個生長命刻，它僅在衝突場景中出現，並代表你花園中的生命週期。
A7: - 你的生長命刻有4個刻度，且每個場景開始時都是空的。
A8: - 在你的回合結束時，如果你的花園中有一顆魔法種子，填充你的生長命刻的1個刻度；接著，如果你的花園中仍然有一顆魔法種子且該魔法種子擁有「在你的回合結束時」的效果（見下文），則應用該效果。
A9: - 當你填滿你的生長命刻的第4個刻度時，移除你花園中的魔法種子，然後清除你的生長命刻的所有刻度。
A10: - 你的生長命刻區段不可被填滿或清除，除非是透過上述方式、透過荊棘之心與綠拇指英雄技能，或透過明確影響生長命刻的效果。
A12: 魔法種子效果
A13: - 魔法種子可以擁有被動效果，或擁有在你的回合結束時、你的生長命刻增加之後觸發的效果。
A14: - 魔法種子的效果僅在它位於你的花園中時適用，且效果隨你的生長命刻當前填滿的區段數量而異。
A15: - 你只應用對應於你的生長命刻中當前填滿區段確切數量的效果，而非其上方或下方的任何效果。
... A19: 你們的團隊也可以合作創造新的魔法種子，且GM可以選擇將它們包含在獎勵中，獨立於你在魔法種子傳記的投入之外獲得。每顆魔法種子價值約1000z；盡力保持這些新魔法種子的強度與標準列表中的相當。
A20: 名稱 | B20: 描述 | C20: 命刻刻度 | D20: 效果
A21: 極地水仙 | B21: 它頑強地生存在冰封之地。 | C21: 0-1 | D21: 你對土屬性和冰屬性傷害具有抗性。
C22: 45691 | D22: 你和場景中你可見的盟友對土屬性和冰屬性傷害具有抗性。
A23: 熾焰菊 | B23: 它厚實的葉瓣酷似一座噴發的火山。 | C23: 45660 | D23: 在你的回合結束時，選擇土屬性或火屬性。直到你再次使用此效果，或此魔法種子不再存在於你的花園中，你和場景中所有盟友造成的所有傷害都變為所選類型，其類型無法改變，且無視抗性。
A24: 沙漠大麗花 | B24: 一種頑強的植物，它不畏懼沙丘的乾燥。 | C24: 0-1 | D24: 你對風屬性和火屬性傷害具有抗性。
C25: 45691 | D25: 你和場景中你可見的盟友對風屬性和火屬性傷害具有抗性。
A26: 黃金銀杏 | B26: 它色彩鮮豔的葉子代表著堅韌。 | C26: 1 | D26: 在你的回合結束時，你和場景中你可見的每個盟友恢復眩暈、憤怒和動搖狀態。
C27: 45691 | D27: 在你的回合結束時，你和場景中你可見的每個盟友恢復等同於【5+你在植生術中SL】的MP。
A28: 墓地阿福花 | B28: 莊嚴而優雅，它像徵著死亡的必然性。 | C28: 1 | D28: 在你的回合結束時，你可以選擇一個你可見的敵人。如果你這樣做，該敵人承受動搖。
C29: 2 | D29: 在你的回合結束時，場景中你可見的每個敵人都承受動搖。
C30: 3 | D30: 在你的回合結束時，你對場景中你可見的每個處於動搖狀態的敵人造成等同於【15+你在植生術中SL】的暗屬性傷害。
A31: 隱士鳶尾 | B31: 它的葉子承載著古老知識的低語。 | C31: 1 | D31: 在你的回合結束時，選擇一個你可見的敵人。遊戲主持人揭示其等級、階級、物種、最大HP、最大MP、特質、屬性、物防和魔防。
C32: 45691 | D32: 在你的回合結束時，選擇一個你可見的敵人。遊戲主持人揭示其等級、階級、物種、最大HP、最大MP、特質、屬性、物防、魔防和相性。
A33: 鉤葉顛茄 | B33: 它紫色的漿果含有致命的魔法毒液。 | C33: 0-1 | D33: 你造成的所有傷害變成毒屬性，其類型無法改變，並無視免疫和抗性。你造成的所有傷害變成毒屬性，其類型無法改變，並無視免疫和抗性。
C34: 45691 | D34: 你造成的所有傷害變成毒屬性，其類型無法改變，並無視免疫和抗性。此外，當你在你的回合內首次造成毒屬性傷害時，你額外造成等同於【你的植生術SL】的傷害，且每個因此失去HP的生物陷入中毒狀態。
A35: 角狀山楂 | B35: 因其淨化特性而受到女巫和外科醫生青睞。 | C35: 0-1 | D35: 你對暗屬性和毒屬性傷害具有抗性。
C36: 45691 | D36: 你和場景中你可見的盟友對暗屬性和毒屬性傷害具有抗性。
A37: 月光玉蘭 | B37: 它在夜晚最黑暗的時分綻放。 | C37: 45660 | D37: 在你的回合結束時，選擇冰屬性或光屬性。直到你再次使用此效果或此魔法種子不再存在於你的花園中，你和場景中所有盟友造成的傷害都變為所選類型，其類型無法改變，並且無視抗性。
A38: 海洋蓮花 | B38: 寧靜與智慧的優雅象徵。 | C38: 0-1 | D38: 你免疫眩暈和緩慢。
C39: 2 | D39: 你將你的DEX和INS視為高一個骰子等級（最高為d12）。
C40: 3 | D40: 你和場景中可見的每個盟友將你的DEX和INS視為高一個骰子等級（最高為d12）。
A41: 朝聖者羚羊花 | B41: 它艷麗的花冠象徵著豐饒。 | C41: 45659 | D41: 在你的回合結束時，選擇你自己或另一個你可見的玩家角色。所選角色恢復2 IP。
C42: 3 | D42: 在你的回合結束時，你和場景中你可見的每個其他玩家角色恢復1 IP。
A43: 蒲公英之舞 | B43: 活力與生機的象徵，它透過暴風傳播種子。 | C43: 45660 | D43: 在你的回合結束時，選擇風屬性或電屬性。直到你再次使用此效果或此魔法種子不再存在於你的花園中，你和場景中所有盟友造成的傷害都變為所選類型，其類型無法改變，並且無視抗性。
A44: 王者帝王花 | B44: 一種色彩繽紛、頑強不屈的花朵，深受古老王朝的青睞。 | C44: 0-1 | D44: 你免疫動搖和虛弱。
C45: 2 | D45: 你將你的MIG和WLP視為高一個骰子等級（最高為d12）。
C46: 3 | D46: 你和場景中你可見的每個盟友將你的MIG和WLP視為高一個骰子等級（最高為d12）。
...

Sheet 祈喚者相關
A1: 現場可用的元素源泉
A2: 在每一個場景中，你周圍的環境都會提供給你兩種不同的元素源泉：GM會告訴你它們是什麼。記得描述元素源泉在場景中的表現；它們可能是某種自然特徵、物體，甚至是生物。
A3: 例如：在一場位於暴風雨中的蒸汽動力飛艇上的戰鬥中，風、電、火、冰中的任意2個元素源泉都可能存在。
A5: 進行元素祈喚
A6: 當你進行一次元素祈喚時，從下表中選擇一個你可以進行的選項(前提是當前場景中有對應的元素源泉)，然後，將其效果作用於一個你能看到的目標。
A7: 你在元素祈喚技能上的等級決定了你可以選擇哪些祈喚：【SL1】開啟「元素爆發」祈喚，【SL2】開啟「元素爆發」和「元素詛咒」祈喚，以及【SL3】開啟所有祈喚。
A8: 例如：如果當前場景中存在風之源泉和土之源泉，且你的元素祈喚技能等級為2，你就可以選擇使用「風元素爆發」、「風元素詛咒」、「土元素爆發」和「土元素詛咒」這4種元素祈喚。
A9: 如果一個元素祈喚能造成傷害或恢復HP或MP，當你達到20級或更高時傷害提高5點，當你達到40級或更高時傷害提高10點。
A10: 與之相似，如果一個元素祈喚能恢復HP或MP，當你達到20級或更高時回復量提高10點，當你達到40級或更高時回復量提高20點。
A12: 元素源泉 | B12: 元素祈喚 | C12: 效果
A13: 風之源泉 | B13: 風元素爆發 | C13: 目標受到20點風屬性傷害。
B14: 風元素詛咒 | C14: 直到你下回合開始前，目標受到任何傷害來源的電屬性和火屬性傷害時受到額外5點傷害。
B15: 微風 | C15: 目標恢復30點HP。
B16: 旋風 | C16: 目標受到10點風屬性傷害並被施加眩暈狀態效果。
A17: 土之源泉 | B17: 土元素爆發 | C17: 目標受到20點土屬性傷害。
B18: 土元素詛咒 | C18: 直到你下回合開始前，目標受到任何傷害來源的風屬性和冰屬性傷害時受到額外5點傷害。
B19: 生長 | C19: 目標恢復30點HP。
B20: 流沙 | C20: 目標受到10點土屬性傷害並被施加緩慢狀態效果。
A21: 火之源泉 | B21: 火元素爆發 | C21: 目標受到20點火屬性傷害。
B22: 火元素詛咒 | C22: 直到你下回合開始前，目標受到任何傷害來源的土屬性和冰屬性傷害時受到額外5點傷害。
B23: 爆裂 | C23: 目標受到10點火屬性傷害並被施加動搖狀態效果。
B24: 煙霧 | C24: 目標損失20點MP並被施加虛弱狀態效果。
A25: 電之源泉 | B25: 電元素爆發 | C25: 目標受到20點電屬性傷害。
B26: 電元素詛咒 | C26: 直到你下回合開始前，目標受到任何傷害來源的土屬性和火屬性傷害時受到額外5點傷害。
B27: 靜電 | C27: 目標受到10點電屬性傷害並被施加緩慢狀態效果。
B28: 雷鳴 | C28: 目標損失20點MP並被施加眩暈狀態效果。
A29: 冰之源泉 | B29: 冰元素爆發 | C29: 目標受到20點冰屬性傷害。
B30: 冰元素詛咒 | C30: 直到你下回合開始前，目標受到任何傷害來源的風屬性和電屬性傷害時受到額外5點傷害。
B31: 凍傷 | C31: 目標受到10點冰屬性傷害並被施加動搖狀態效果。
B32: 寒冷 | C32: 目標損失20點MP並被施加虛弱狀態效果。

Sheet 機師相關
A1: 機師的載具
A2: 機師的個人載具遵循一套特殊規則。
A3: 在衝突中搭乘個人載具需要執行「目標」動作。通常不需要進行檢定，但如果存在嚴重的危險或障礙，遊戲主持人可以引入一個「命刻」。
A4: 如果在衝突開始時個人載具是可以搭乘的，角色可以在「先攻檢定」之前立即搭乘它（核心規則書，第 59 頁）。
A5: 離開個人載具不需要消耗動作，但在衝突期間，只能在你的回合進行，且只能在沒有其他效果正在結算時進行。
A6: 根據其框架和模組，個人載具可以容納數量不定的人類體型生物，但只有其機師可以駕駛它。此外，其他乘客在執行「防禦」動作時不能掩護其他生物。
A7: 個人載具上可同時啟用的模組最大數量等於 3 + 機師在「個人載具」技能上的等級。
A8: 在衝突之外，機師可以自由重新分配其個人載具上啟用和停用的模組；這個最大限制的優先級始終高於任何其他效果（例如，當你透過「靈活配置」啟用模組時）。
A10: 個人載具由以下元素組成：
A11: 決定其整體外型的框架： 戰馬適用於騎乘動物、摩托車、小型星際戰機、滑板等；外骨骼適用於動力裝甲和機械義肢；機甲適用於從內部駕駛的大型戰鬥機器人。
A12: 每個機師在獲得該技能時必須為他們的個人載具選擇框架。這在遊戲期間內無法改變，因此請務必根據角色的風格和個性仔細選擇，並考慮他們在戰役中將扮演的角色。
A13: 例如，如果你的故事發生在賽博龐克大都會的貧民窟中，選擇一架戰鬥機就說不通（換成反重力摩托車如何？）。
... A60: 框架清單
A61: 框架名稱 | B61: 乘客上限 | C61: 距離 | D61: 裝備限制與特殊規則
A62: 外骨骼 | B62: 0 | C62: 無影響 | D62: 可裝備至多 2 個啟動狀態武裝模組、至多 1 個啟動狀態防具模組和任意數量的啟動狀態支援模組。 如果你在此載具上使用「壓縮技術」技能，它不需要消耗 IP。
A63: 機甲 | B63: 0 | C63: ×2 | D63: 可裝備至多 2 個啟動狀態武裝模組、至多 1 個啟動狀態防具模組和任意數量的啟動狀態支援模組。
A64: 戰馬 | B64: 至多 1 名 | C64: ×2 | D64: 可裝備至多 1 個啟動狀態武裝模組、至多 1 個啟動狀態防具模組和任意數量的啟動狀態支援模組。 如果你在此載具上使用「引擎之心」技能，它不需要消耗 MP。
A65: 「乘客」指的是除了機師以外可運送的人形生物；「距離」指的是一個旅行日中所行駛的距離。請記住，載具上的啟動狀態模組的最大數量取決於你的「個人載具」技能等級。
A67: 防具模組清單
A68: 模組名稱 | B68: 物防 (DEF) | C68: 魔防 (MDEF)
A69: 柔性鍍層模組 | B69: DEX size +2 | C69: INS size +1
A70: 重裝鍍層模組✦ | B70: 12 | C70: 8
A71: 符文鍍層模組✦ | B71: 10 | C71: 11
A72: 標準鍍層模組✦ | B72: 11 | C72: 10
A73: 這些增益僅適用於駕駛著載具的機師；你可以透過裝備「鍍層擴展模組」來將重裝鍍層、符文鍍層和標準鍍層的效果擴展給乘客。
A75: 武裝模組清單
A76: 模組名稱 | B76: 命中檢定 | C76: 傷害 | D76: 攻擊類型 | E76: 武器類別 | F76: 特殊規則與限制
A77: 奧術模組 | B77: 【DEX+WLP】 | C77: 【HR+8】物理 | D77: 近戰 | E77: 奧術 | F77: 無
A78: 斧模組 | B78: 【DEX+INS】 | C78: 【HR+12】物理 | D78: 近戰 | E78: 重型 | F78: 無
A79: 刀刃模組 | B79: 【DEX+INS】+1 | C79: 【HR+6】物理 | D79: 近戰 | E79: 匕首 | F79: 無
A80: 弓模組 | B80: 【DEX+INS】+1 | C80: 【HR+12】物理 | D80: 遠程 | E80: 弓 | F80: 啟動時載具上不能裝備其他啟動的武裝模組。
A81: 火砲模組 | B81: 【DEX+INS】 | C81: 【HR+14】物理 | D81: 遠程 | E81: 火器 | F81: 啟動時載具上不能裝備其他啟動的武裝模組。
A82: 爪模組 | B82: 【DEX+INS】 | C82: 【HR+8】物理 | D82: 近戰 | E82: 格鬥 | F82: 可以像空手一樣與場景互動。
A83: 大劍模組 | B83: 【DEX+INS】+1 | C83: 【HR+14】物理 | D83: 近戰 | E83: 劍 | F83: 啟動時載具上不能裝備其他啟動的武裝模組。
A84: 高能量奧術模組 | B84: 【DEX+WLP】 | C84: 【HR+12】物理 | D84: 近戰 | E84: 奧術 | F84: 啟動時載具上不能裝備其他啟動的武裝模組。
A85: 連枷模組 | B85: 【DEX+INS】 | C85: 【HR+10】物理 | D85: 近戰 | E85: 連枷 | F85: 無
A86: 火焰噴射模組 | B86: 【DEX+INS】 | C86: 【HR+8】火屬性 | D86: 遠程 | E86: 火器 | F86: 無
A87: 機關槍模組 | B87: 【DEX+INS】 | C87: 【HR+10】物理 | D87: 遠程 | E87: 火器 | F87: 啟動時載具上不能裝備其他啟動的武裝模組。 使用該武裝模組進行攻擊動作時，你可以執行兩次單獨的攻擊（針對同一個目標或不同目標）。 如果你這樣做了，兩次攻擊都遵循雙武器戰鬥的規則：每次攻擊都失去多重且無法獲得，並且在確定傷害時HR視為0。
... A93: 三叉戟模組 | B93: 【DEX+INS】+1 | C93: 【HR+14】物理 | D93: 近戰 | E93: 矛 | F93: 啟動時載具上不能裝備其他啟動的武裝模組。
A95: 支援模組清單
...

Sheet 魔奏師相關
A1: 演唱樂句
A2: 當你演唱一首樂句時，你會結合你所學的音量、音調和曲風。這三個要素決定了該樂句的 MP 消耗、目標以及效果。
A3: - 音量決定了樂句的聲音強度以及你能影響到的生物。
A4: - 每一個曲風決定了樂句的整體效果。
A5: - 每一個音調都有其對應的傷害類型、狀態效果、屬性以及恢復類型。這些要素會修飾由樂句曲風所決定的效果。
A6: 範例：你可以將低音量、熾熱音調與縈繞曲風結合，花費 10 點 MP 對單一生物施加動搖狀態；或者你可以將中音量、鋼鐵音調與活力曲風結合，讓你的盟友在使用WLP屬性時，能在命刻上獲得額外的進度。
A8: 音量 VOLUME | G8: 歌單！ | I8: 下滑複製此欄為樂句效果！
A9: 音量 | B9: MP | C9: 目標 | G9: 音量 | H9: 高 | I9: ="【目標】" & N10 -> 【目標】所有能聽到你的敵人 | M9: MP消耗 | N9: =IFERROR(VLOOKUP(H9,A10:C12,2,FALSE), "") -> 30
A10: 低 | B10: 10 | C10: 自己或一個能聽到你的生物 | G10: 音調 | H10: 鋼鐵 | I10: ="【花費】" & N9 & " MP" -> 【花費】30 MP | M10: 目標 | N10: =IFERROR(VLOOKUP(H9,A10:C12,3,FALSE), "") -> 所有能聽到你的敵人
A11: 中 | B11: 20 | C11: 所有能聽到你的盟友 | G11: 曲風 | H11: 縈繞 | I11: ="【效果】" & SUBSTITUTE(SUBSTITUTE(SUBSTITUTE(SUBSTITUTE(N15, "【音調恢復】", "【"&N14&"】"), "【音調屬性】", "【"&N13&"】"), "【音調類型】", "【"&N11&"】"), "【音調狀態】", "【"&N12&"】") -> 【效果】每個目標獲得【緩慢】。此外，每個目標失去對【物理】的抗性，直到你的下個回合開始。 | M11: 類型 | N11: =IFERROR(VLOOKUP(H10,A16:E23,2,FALSE), "") -> 物理
A12: 高 | B12: 30 | C12: 所有能聽到你的敵人 | M12: 狀態 | N12: =IFERROR(VLOOKUP(H10,A16:E23,3,FALSE), "") -> 緩慢
M13: 屬性 | N13: =IFERROR(VLOOKUP(H10,A16:E23,4,FALSE), "") -> WLP
A14: 音調 KEY | M14: 恢復 | N14: =IFERROR(VLOOKUP(H10,A16:E23,5,FALSE), "") -> MP
A15: 音調 | B15: 類型 | C15: 狀態 | D15: 屬性 | E15: 恢復 | M15: 原始效果 | N15: =IFERROR(VLOOKUP(H11,A27:F33,2,FALSE), "") -> 每個目標獲得【音調狀態】。此外，每個目標失去對【音調類型】的抗性，直到你的下個回合開始。
A16: 熾熱 | B16: 火 | C16: 動搖 | D16: MIG | E16: HP
A17: 霜凍 | B17: 冰 | C17: 虛弱 | D17: WLP | E17: MP
A18: 鋼鐵 | B18: 物理 | C18: 緩慢 | D18: WLP | E18: MP
A19: 輝光 | B19: 光 | C19: 眩暈 | D19: INS | E19: HP
A20: 暗影 | B20: 暗 | C20: 虛弱 | D20: DEX | E20: MP
A21: 堅石 | B21: 土 | C21: 眩暈 | D21: MIG | E21: HP
A22: 閃雷 | B22: 電 | C22: 動搖 | D22: DEX | E22: HP
A23: 疾風 | B23: 風 | C23: 緩慢 | D23: INS | E23: MP
A25: 曲風 TONE
A26: 曲風 | B26: 效果
A27: 冷靜 | B27: 所有目標恢復【10+2*你當前WLP骰尺寸】點的【音調恢復】。當你的角色等級達到20級時，這個數值提升10點；達到40級時提升20點。如果用來恢復MP，則對演奏者自身無效。
A28: 激情 | B28: 直到你的下個回合開始，當一個目標成功通過某個使用了【音調屬性】的檢定，並且這個檢定能讓他推進或迴轉命刻時，他能選擇推進或迴轉1個額外部分。
A29: 瘋狂 | B29: 每個目標受到【2*你當前WLP骰尺寸】點【音調類型】的傷害。當你的角色等級達到20級時，這個數值提升5點；達到40級時提升10點。
A30: 縈繞 | B30: 每個目標獲得【音調狀態】。此外，每個目標失去對【音調類型】的抗性，直到你的下個回合開始。
A31: 生動 | B31: 每個目標的【音調屬性】骰尺寸增加一級（最高為d12），直到你的下個回合開始。
A32: 洶湧 | B32: 直到你的下個回合開始，每個目標在首次受到傷害時，那個傷害被轉換為【音調類型】每個目標只會觸發一次此效果，且只影響其自身。
A33: 莊嚴 | B33: 每個目標從【音調狀態】中恢復。此外，每個目標獲得對【音調類型】的抗性，直到你的下個回合開始。

Sheet 阿爾克納
A1: 名字 | B1: 領域 | C1: 連接 | D1: 解除
A2: 鍛造之阿爾卡納 | B2: 火、熱、金屬。 | C2: 你對火屬性傷害有抗性。 你造成的任何火屬性傷害都會忽略抗性。 | D2: 當你解除此阿爾卡納時，選擇觸發鍛造或煉獄： 鍛造。你創造了一件你選擇的基本防具、盾牌或武器（見130~133頁）如果你多次鍛造，只有最新一次創造的裝備會留下。如果你以這種方式創造武器，它將造成火屬性傷害而不是物理傷害。 煉獄。選擇你能看到的任意數量的生物：它們中的每一個都會受到30點的火屬性傷害。這個傷害無視抗性。
A3: 霜之阿爾卡納 | B3: 寒冷，冰，沉默 | C3: 你對冰屬性傷害有抗性，對憤怒免疫。你 造成的任何冰屬性傷害都無視抗性 | D3: 冰雪時代。選擇你能看到的任意數量的生物：它們中的每一個都會受到30點的冰屬性傷害。這個傷害無視抗性。
A4: 門之阿爾卡納 | B4: 空間，旅行，虛空 | C4: 你對暗屬性傷害有抗性 你的魔防獲得+1加值 | D4: 當你解除這個阿爾卡納時，請選擇湮滅或折躍。 湮滅：選擇你能看到的任何數量的生物：他們每個人都會受到30點的暗屬性傷害。這個傷害無視抗性。 折躍：你將自己和附近最多五個願意的生物傳送到你之前去過的地方，但是與那個地方的路程需要在1個旅行日之內。
A5: 魔典之阿爾卡納 | B5: 知識、啟示、理解。 | C5: 你能夠讀、寫、說、理解所有語言 你的INS骰尺寸提升一階(最高為d12) | D5: 神諭：你向GM提出一個問題。 GM必須如實回答，描述魔法書向你展示的願景。 使用後這個解除效果直到下個黎明才能再次使用。此外，同一個問題不可以被多次問到，GM有對哪些問題太過相似而不能再問的決定權。
A6: 橡樹之阿爾卡納 | B6: 大地、植物、毒藥 | C6: 你對地屬性和毒屬性傷害有抗性，對中毒免疫。 每當你恢復HP時，你會額外恢復5點HP。 | D6: 開花：選擇你能看到的任何數量的生物(你也可以選擇你自己)：它們中的每一個都能從中毒狀態中恢復，並恢復40點HP。如果你的角色等級大於等於20級，這個數量會增加到50點HP，如果你的角色等級大於等於40級，會增加到60點HP。
A7: 天空之阿爾卡納 | B7: 霧、雨、風暴。 | C7: 你對風屬性和電屬性傷害有抗性。 你可以使用一個動作來準確預測第二天在兩個旅行日的行程範圍內的天氣狀況——GM會告訴你天氣狀況如 | D7: 雷暴：選擇你能看到的任何數量的生物：它們中的每一個都會受到30點電屬性傷害。此傷害無視抗性。
A8: 劍之阿爾卡納 | B8: 征服、英雄主義、領導力。 | C8: 你的攻擊會造成5點額外傷害，並且你的攻擊所造成的所有傷害都被視為無屬性(因此不受傷害親和度的影響)。只要你與這個阿爾卡納連結，你的攻擊所造成的傷害就不能獲得任何傷害類型。當你進行攻擊時，你可以讓該攻擊獲得多重(任意數量的目標)屬性。如果你這樣做了，在攻擊結算後，這個阿爾卡納將被自動解除(這不被視為自願解除)。
A9: 塔之阿爾卡納 | B9: 審判、保護、獻祭 | C9: 當你召喚這個阿爾卡納時，選擇一種傷害類型：風、電、暗、土、火或冰。在這個阿爾卡納被解除之前，你在場景內的每個盟友都對所選的傷害類型有抗性(你不會獲得抗性)。 | D9: 審判：選擇你能看到的任何數量的生物：它們中的每一個都會受到30點光屬性傷害。
A10: 輪之阿爾卡納 | B10: 命運，速度，時間 | C10: 你對緩慢狀態免疫。 你的物防獲得+1加值 | D10: 時間凍結：選擇任意數量的你能看到的生物：它們中的每一個都會獲得緩慢狀態。如果這樣選擇的生物已經在緩慢狀態中了，那麼該生物在他的下一回合中會減少一個動作(最少為0動作)。

Sheet 更新日誌
A1: 時間 | B1: 版本 | C1: 概要
A2: 2025.6.21 | B2: V2.4 | C2: 把目前的簡中全數轉成繁中，同時簡單的修改幾個英文 By有強迫症的人
A3: 2025.9.18 | B3: V2.5 | C3: 修正了部分DLC技能——徽記技能的描述，使其符合原版翻譯 By上班偷懶的人
A4: 2025.10.14 | B4: V2.6 | C4: 修正了部分DLC技能——混合形態的描述，使其符合原版翻譯 By上班偷懶的人
C5: 修正了部分DLC職業——祈喚者的描述，使其符合原版翻譯 By上班偷懶的人
C6: 修正了部分英雄技能——徽記師相關，使其符合原版翻譯 By上班偷懶的人
C7: 修正了部分英雄技能——魔奏者相關，使其符合原版翻譯 By上班偷懶的人
A8: 2025.10.15 | B8: V2.7 | C8: 增添了心靈天賦的列表 By上班偷懶的人
A9: 2025.12.27 | B9: V2.8 | C9: 修正了部分DLC職業——植物學家的描述，使其符合原版翻譯 By上班偷懶的人
C10: 增添了【植物學家相關】頁面 By上班偷懶的人
A11: 2026.01.05 | B11: V2.9 | C11: 增添了【祈喚者相關】頁面 By上班偷懶的人
A12: 2026.01.06 | B12: V2.10 | C12: 修正機師額外表的激活模塊公式
A13: 2026.01.08 | B13: V2.11 | C13: 修正了部分DLC職業——舞者的描述，使其符合原版翻譯 By上班偷懶的人
C14: 修正了部分DLC技能——舞步的描述，使其符合原版翻譯 By上班偷懶的人
A15: 2026.01.09 | B15: V2.12 | C15: 將附加表全都翻譯為繁中(除了沒人愛的王牌) By有強迫症的人
A16: 2026.02.03 | B16: V2.13 | C16: 修正了所有英雄技能的描述，使其符合原版翻譯與最新補丁By上班偷懶的人
A17: 2026.03.10 | B17: V2.14 | C17: 修改了Playtest版突變者混合變形相關技能相關的補丁By上班偷懶的人
A18: 2026.03.17 | B18: V2.15 | C18: 修改了Playtest版秘儀師技能相關的補丁By上班偷懶的人
A19: 2026.04.02 | B19: V2.16 | C19: 增添了【機師相關】頁面 By上班偷懶的人
A20: 2026.08.30 | B20: V2.17 | C20: 增添了【魔奏師相關】頁面，附上【歌單！】內容
